{
 "cells": [
  {
   "cell_type": "markdown",
   "id": "19c740a5",
   "metadata": {},
   "source": [
    "## Multiclass Classification with the Iris Flowers Dataset -  ANN classification"
   ]
  },
  {
   "cell_type": "code",
   "execution_count": 1,
   "id": "de07e8a9",
   "metadata": {},
   "outputs": [],
   "source": [
    "# importing required packages\n",
    "\n",
    "import numpy as np\n",
    "import pandas as pd\n",
    "\n",
    "from sklearn.model_selection import train_test_split\n",
    "\n",
    "import tensorflow as tf\n",
    "from tensorflow.keras.wrappers.scikit_learn import KerasClassifier\n",
    "from tensorflow.keras.models import Sequential\n",
    "from tensorflow.keras.layers import Dense\n",
    "\n",
    "from tensorflow.keras import utils\n",
    "\n",
    "from sklearn.model_selection import StratifiedKFold # for k-fold validation\n",
    "from sklearn.model_selection import KFold\n",
    "\n",
    "from sklearn.model_selection import cross_val_score\n",
    "\n",
    "from sklearn.preprocessing import LabelEncoder\n",
    "\n",
    "from sklearn.pipeline import Pipeline"
   ]
  },
  {
   "cell_type": "code",
   "execution_count": 2,
   "id": "6e6dae55",
   "metadata": {},
   "outputs": [],
   "source": [
    "# fix random seed for reproducibility\n",
    "\n",
    "seed = 7\n",
    "np.random.seed(seed)"
   ]
  },
  {
   "cell_type": "code",
   "execution_count": 3,
   "id": "90e093c9",
   "metadata": {},
   "outputs": [],
   "source": [
    "# importing the dataset\n",
    "\n",
    "location = \"C:/DevelopmentPlayground/Datasets/iris.csv\"\n",
    "\n",
    "dataset = pd.read_csv(location)"
   ]
  },
  {
   "cell_type": "code",
   "execution_count": 4,
   "id": "659d32e8",
   "metadata": {},
   "outputs": [
    {
     "data": {
      "text/plain": [
       "(150, 6)"
      ]
     },
     "execution_count": 4,
     "metadata": {},
     "output_type": "execute_result"
    }
   ],
   "source": [
    "dataset.shape"
   ]
  },
  {
   "cell_type": "code",
   "execution_count": 5,
   "id": "14c69cf1",
   "metadata": {},
   "outputs": [
    {
     "data": {
      "text/html": [
       "<div>\n",
       "<style scoped>\n",
       "    .dataframe tbody tr th:only-of-type {\n",
       "        vertical-align: middle;\n",
       "    }\n",
       "\n",
       "    .dataframe tbody tr th {\n",
       "        vertical-align: top;\n",
       "    }\n",
       "\n",
       "    .dataframe thead th {\n",
       "        text-align: right;\n",
       "    }\n",
       "</style>\n",
       "<table border=\"1\" class=\"dataframe\">\n",
       "  <thead>\n",
       "    <tr style=\"text-align: right;\">\n",
       "      <th></th>\n",
       "      <th>Id</th>\n",
       "      <th>SepalLengthCm</th>\n",
       "      <th>SepalWidthCm</th>\n",
       "      <th>PetalLengthCm</th>\n",
       "      <th>PetalWidthCm</th>\n",
       "      <th>Species</th>\n",
       "    </tr>\n",
       "  </thead>\n",
       "  <tbody>\n",
       "    <tr>\n",
       "      <th>0</th>\n",
       "      <td>1</td>\n",
       "      <td>5.1</td>\n",
       "      <td>3.5</td>\n",
       "      <td>1.4</td>\n",
       "      <td>0.2</td>\n",
       "      <td>Iris-setosa</td>\n",
       "    </tr>\n",
       "    <tr>\n",
       "      <th>1</th>\n",
       "      <td>2</td>\n",
       "      <td>4.9</td>\n",
       "      <td>3.0</td>\n",
       "      <td>1.4</td>\n",
       "      <td>0.2</td>\n",
       "      <td>Iris-setosa</td>\n",
       "    </tr>\n",
       "    <tr>\n",
       "      <th>2</th>\n",
       "      <td>3</td>\n",
       "      <td>4.7</td>\n",
       "      <td>3.2</td>\n",
       "      <td>1.3</td>\n",
       "      <td>0.2</td>\n",
       "      <td>Iris-setosa</td>\n",
       "    </tr>\n",
       "    <tr>\n",
       "      <th>3</th>\n",
       "      <td>4</td>\n",
       "      <td>4.6</td>\n",
       "      <td>3.1</td>\n",
       "      <td>1.5</td>\n",
       "      <td>0.2</td>\n",
       "      <td>Iris-setosa</td>\n",
       "    </tr>\n",
       "    <tr>\n",
       "      <th>4</th>\n",
       "      <td>5</td>\n",
       "      <td>5.0</td>\n",
       "      <td>3.6</td>\n",
       "      <td>1.4</td>\n",
       "      <td>0.2</td>\n",
       "      <td>Iris-setosa</td>\n",
       "    </tr>\n",
       "  </tbody>\n",
       "</table>\n",
       "</div>"
      ],
      "text/plain": [
       "   Id  SepalLengthCm  SepalWidthCm  PetalLengthCm  PetalWidthCm      Species\n",
       "0   1            5.1           3.5            1.4           0.2  Iris-setosa\n",
       "1   2            4.9           3.0            1.4           0.2  Iris-setosa\n",
       "2   3            4.7           3.2            1.3           0.2  Iris-setosa\n",
       "3   4            4.6           3.1            1.5           0.2  Iris-setosa\n",
       "4   5            5.0           3.6            1.4           0.2  Iris-setosa"
      ]
     },
     "execution_count": 5,
     "metadata": {},
     "output_type": "execute_result"
    }
   ],
   "source": [
    "dataset.head()"
   ]
  },
  {
   "cell_type": "code",
   "execution_count": 6,
   "id": "d1b4b3e3",
   "metadata": {},
   "outputs": [],
   "source": [
    "# Spliting the dataset into X and Y\n",
    "\n",
    "# X = dataset.iloc[:, 1:4].values\n",
    "# Y = dataset.iloc[:, -1].values\n",
    "dataset = dataset.values\n",
    "X = dataset[:, 0:4].astype(float)\n",
    "Y = dataset[:, 4]"
   ]
  },
  {
   "cell_type": "code",
   "execution_count": 7,
   "id": "5d183b68",
   "metadata": {},
   "outputs": [
    {
     "data": {
      "text/plain": [
       "array([[  1. ,   5.1,   3.5,   1.4],\n",
       "       [  2. ,   4.9,   3. ,   1.4],\n",
       "       [  3. ,   4.7,   3.2,   1.3],\n",
       "       [  4. ,   4.6,   3.1,   1.5],\n",
       "       [  5. ,   5. ,   3.6,   1.4],\n",
       "       [  6. ,   5.4,   3.9,   1.7],\n",
       "       [  7. ,   4.6,   3.4,   1.4],\n",
       "       [  8. ,   5. ,   3.4,   1.5],\n",
       "       [  9. ,   4.4,   2.9,   1.4],\n",
       "       [ 10. ,   4.9,   3.1,   1.5],\n",
       "       [ 11. ,   5.4,   3.7,   1.5],\n",
       "       [ 12. ,   4.8,   3.4,   1.6],\n",
       "       [ 13. ,   4.8,   3. ,   1.4],\n",
       "       [ 14. ,   4.3,   3. ,   1.1],\n",
       "       [ 15. ,   5.8,   4. ,   1.2],\n",
       "       [ 16. ,   5.7,   4.4,   1.5],\n",
       "       [ 17. ,   5.4,   3.9,   1.3],\n",
       "       [ 18. ,   5.1,   3.5,   1.4],\n",
       "       [ 19. ,   5.7,   3.8,   1.7],\n",
       "       [ 20. ,   5.1,   3.8,   1.5],\n",
       "       [ 21. ,   5.4,   3.4,   1.7],\n",
       "       [ 22. ,   5.1,   3.7,   1.5],\n",
       "       [ 23. ,   4.6,   3.6,   1. ],\n",
       "       [ 24. ,   5.1,   3.3,   1.7],\n",
       "       [ 25. ,   4.8,   3.4,   1.9],\n",
       "       [ 26. ,   5. ,   3. ,   1.6],\n",
       "       [ 27. ,   5. ,   3.4,   1.6],\n",
       "       [ 28. ,   5.2,   3.5,   1.5],\n",
       "       [ 29. ,   5.2,   3.4,   1.4],\n",
       "       [ 30. ,   4.7,   3.2,   1.6],\n",
       "       [ 31. ,   4.8,   3.1,   1.6],\n",
       "       [ 32. ,   5.4,   3.4,   1.5],\n",
       "       [ 33. ,   5.2,   4.1,   1.5],\n",
       "       [ 34. ,   5.5,   4.2,   1.4],\n",
       "       [ 35. ,   4.9,   3.1,   1.5],\n",
       "       [ 36. ,   5. ,   3.2,   1.2],\n",
       "       [ 37. ,   5.5,   3.5,   1.3],\n",
       "       [ 38. ,   4.9,   3.1,   1.5],\n",
       "       [ 39. ,   4.4,   3. ,   1.3],\n",
       "       [ 40. ,   5.1,   3.4,   1.5],\n",
       "       [ 41. ,   5. ,   3.5,   1.3],\n",
       "       [ 42. ,   4.5,   2.3,   1.3],\n",
       "       [ 43. ,   4.4,   3.2,   1.3],\n",
       "       [ 44. ,   5. ,   3.5,   1.6],\n",
       "       [ 45. ,   5.1,   3.8,   1.9],\n",
       "       [ 46. ,   4.8,   3. ,   1.4],\n",
       "       [ 47. ,   5.1,   3.8,   1.6],\n",
       "       [ 48. ,   4.6,   3.2,   1.4],\n",
       "       [ 49. ,   5.3,   3.7,   1.5],\n",
       "       [ 50. ,   5. ,   3.3,   1.4],\n",
       "       [ 51. ,   7. ,   3.2,   4.7],\n",
       "       [ 52. ,   6.4,   3.2,   4.5],\n",
       "       [ 53. ,   6.9,   3.1,   4.9],\n",
       "       [ 54. ,   5.5,   2.3,   4. ],\n",
       "       [ 55. ,   6.5,   2.8,   4.6],\n",
       "       [ 56. ,   5.7,   2.8,   4.5],\n",
       "       [ 57. ,   6.3,   3.3,   4.7],\n",
       "       [ 58. ,   4.9,   2.4,   3.3],\n",
       "       [ 59. ,   6.6,   2.9,   4.6],\n",
       "       [ 60. ,   5.2,   2.7,   3.9],\n",
       "       [ 61. ,   5. ,   2. ,   3.5],\n",
       "       [ 62. ,   5.9,   3. ,   4.2],\n",
       "       [ 63. ,   6. ,   2.2,   4. ],\n",
       "       [ 64. ,   6.1,   2.9,   4.7],\n",
       "       [ 65. ,   5.6,   2.9,   3.6],\n",
       "       [ 66. ,   6.7,   3.1,   4.4],\n",
       "       [ 67. ,   5.6,   3. ,   4.5],\n",
       "       [ 68. ,   5.8,   2.7,   4.1],\n",
       "       [ 69. ,   6.2,   2.2,   4.5],\n",
       "       [ 70. ,   5.6,   2.5,   3.9],\n",
       "       [ 71. ,   5.9,   3.2,   4.8],\n",
       "       [ 72. ,   6.1,   2.8,   4. ],\n",
       "       [ 73. ,   6.3,   2.5,   4.9],\n",
       "       [ 74. ,   6.1,   2.8,   4.7],\n",
       "       [ 75. ,   6.4,   2.9,   4.3],\n",
       "       [ 76. ,   6.6,   3. ,   4.4],\n",
       "       [ 77. ,   6.8,   2.8,   4.8],\n",
       "       [ 78. ,   6.7,   3. ,   5. ],\n",
       "       [ 79. ,   6. ,   2.9,   4.5],\n",
       "       [ 80. ,   5.7,   2.6,   3.5],\n",
       "       [ 81. ,   5.5,   2.4,   3.8],\n",
       "       [ 82. ,   5.5,   2.4,   3.7],\n",
       "       [ 83. ,   5.8,   2.7,   3.9],\n",
       "       [ 84. ,   6. ,   2.7,   5.1],\n",
       "       [ 85. ,   5.4,   3. ,   4.5],\n",
       "       [ 86. ,   6. ,   3.4,   4.5],\n",
       "       [ 87. ,   6.7,   3.1,   4.7],\n",
       "       [ 88. ,   6.3,   2.3,   4.4],\n",
       "       [ 89. ,   5.6,   3. ,   4.1],\n",
       "       [ 90. ,   5.5,   2.5,   4. ],\n",
       "       [ 91. ,   5.5,   2.6,   4.4],\n",
       "       [ 92. ,   6.1,   3. ,   4.6],\n",
       "       [ 93. ,   5.8,   2.6,   4. ],\n",
       "       [ 94. ,   5. ,   2.3,   3.3],\n",
       "       [ 95. ,   5.6,   2.7,   4.2],\n",
       "       [ 96. ,   5.7,   3. ,   4.2],\n",
       "       [ 97. ,   5.7,   2.9,   4.2],\n",
       "       [ 98. ,   6.2,   2.9,   4.3],\n",
       "       [ 99. ,   5.1,   2.5,   3. ],\n",
       "       [100. ,   5.7,   2.8,   4.1],\n",
       "       [101. ,   6.3,   3.3,   6. ],\n",
       "       [102. ,   5.8,   2.7,   5.1],\n",
       "       [103. ,   7.1,   3. ,   5.9],\n",
       "       [104. ,   6.3,   2.9,   5.6],\n",
       "       [105. ,   6.5,   3. ,   5.8],\n",
       "       [106. ,   7.6,   3. ,   6.6],\n",
       "       [107. ,   4.9,   2.5,   4.5],\n",
       "       [108. ,   7.3,   2.9,   6.3],\n",
       "       [109. ,   6.7,   2.5,   5.8],\n",
       "       [110. ,   7.2,   3.6,   6.1],\n",
       "       [111. ,   6.5,   3.2,   5.1],\n",
       "       [112. ,   6.4,   2.7,   5.3],\n",
       "       [113. ,   6.8,   3. ,   5.5],\n",
       "       [114. ,   5.7,   2.5,   5. ],\n",
       "       [115. ,   5.8,   2.8,   5.1],\n",
       "       [116. ,   6.4,   3.2,   5.3],\n",
       "       [117. ,   6.5,   3. ,   5.5],\n",
       "       [118. ,   7.7,   3.8,   6.7],\n",
       "       [119. ,   7.7,   2.6,   6.9],\n",
       "       [120. ,   6. ,   2.2,   5. ],\n",
       "       [121. ,   6.9,   3.2,   5.7],\n",
       "       [122. ,   5.6,   2.8,   4.9],\n",
       "       [123. ,   7.7,   2.8,   6.7],\n",
       "       [124. ,   6.3,   2.7,   4.9],\n",
       "       [125. ,   6.7,   3.3,   5.7],\n",
       "       [126. ,   7.2,   3.2,   6. ],\n",
       "       [127. ,   6.2,   2.8,   4.8],\n",
       "       [128. ,   6.1,   3. ,   4.9],\n",
       "       [129. ,   6.4,   2.8,   5.6],\n",
       "       [130. ,   7.2,   3. ,   5.8],\n",
       "       [131. ,   7.4,   2.8,   6.1],\n",
       "       [132. ,   7.9,   3.8,   6.4],\n",
       "       [133. ,   6.4,   2.8,   5.6],\n",
       "       [134. ,   6.3,   2.8,   5.1],\n",
       "       [135. ,   6.1,   2.6,   5.6],\n",
       "       [136. ,   7.7,   3. ,   6.1],\n",
       "       [137. ,   6.3,   3.4,   5.6],\n",
       "       [138. ,   6.4,   3.1,   5.5],\n",
       "       [139. ,   6. ,   3. ,   4.8],\n",
       "       [140. ,   6.9,   3.1,   5.4],\n",
       "       [141. ,   6.7,   3.1,   5.6],\n",
       "       [142. ,   6.9,   3.1,   5.1],\n",
       "       [143. ,   5.8,   2.7,   5.1],\n",
       "       [144. ,   6.8,   3.2,   5.9],\n",
       "       [145. ,   6.7,   3.3,   5.7],\n",
       "       [146. ,   6.7,   3. ,   5.2],\n",
       "       [147. ,   6.3,   2.5,   5. ],\n",
       "       [148. ,   6.5,   3. ,   5.2],\n",
       "       [149. ,   6.2,   3.4,   5.4],\n",
       "       [150. ,   5.9,   3. ,   5.1]])"
      ]
     },
     "execution_count": 7,
     "metadata": {},
     "output_type": "execute_result"
    }
   ],
   "source": [
    "X.astype(float)"
   ]
  },
  {
   "cell_type": "code",
   "execution_count": 8,
   "id": "7bc09a69",
   "metadata": {},
   "outputs": [
    {
     "name": "stdout",
     "output_type": "stream",
     "text": [
      "Encoded Y : [ 1  1  1  1  1  3  2  1  1  0  1  1  0  0  1  3  3  2  2  2  1  3  1  4\n",
      "  1  1  3  1  1  1  1  3  0  1  0  1  1  0  1  1  2  2  1  5  3  2  1  1\n",
      "  1  1 10 11 11  9 11  9 12  6  9 10  6 11  6 10  9 10 11  6 11  7 14  9\n",
      " 11  8  9 10 10 13 11  6  7  6  8 12 11 12 11  9  9  9  8 10  8  6  9  8\n",
      "  9  9  7  9 21 15 17 14 18 17 13 14 14 21 16 15 17 16 20 19 14 18 19 11\n",
      " 19 16 16 14 17 14 14 14 17 12 15 16 18 11 10 19 20 14 14 17 20 19 15 19\n",
      " 21 19 15 16 19 14]\n"
     ]
    }
   ],
   "source": [
    "# Encoding the class values as integers\n",
    "\n",
    "lblencoder = LabelEncoder()\n",
    "lblencoder.fit(Y)\n",
    "encoded_Y = lblencoder.transform(Y)\n",
    "\n",
    "print('Encoded Y :', encoded_Y)"
   ]
  },
  {
   "cell_type": "code",
   "execution_count": 9,
   "id": "00141d3a",
   "metadata": {},
   "outputs": [],
   "source": [
    "# Convert the integers to dummy variables i.e., one hot encoding\n",
    "\n",
    "dummy_y = utils.to_categorical(encoded_Y)"
   ]
  },
  {
   "cell_type": "code",
   "execution_count": 10,
   "id": "e3f3b336",
   "metadata": {},
   "outputs": [
    {
     "name": "stdout",
     "output_type": "stream",
     "text": [
      "dummy_y : \n",
      " [[0. 1. 0. ... 0. 0. 0.]\n",
      " [0. 1. 0. ... 0. 0. 0.]\n",
      " [0. 1. 0. ... 0. 0. 0.]\n",
      " ...\n",
      " [0. 0. 0. ... 0. 0. 0.]\n",
      " [0. 0. 0. ... 1. 0. 0.]\n",
      " [0. 0. 0. ... 0. 0. 0.]]\n"
     ]
    }
   ],
   "source": [
    "print('dummy_y : \\n', dummy_y)"
   ]
  },
  {
   "cell_type": "code",
   "execution_count": 11,
   "id": "81428e17",
   "metadata": {},
   "outputs": [
    {
     "name": "stdout",
     "output_type": "stream",
     "text": [
      "type(X) : <class 'numpy.ndarray'>\n",
      "type(dummy_y) : <class 'numpy.ndarray'>\n"
     ]
    }
   ],
   "source": [
    "print('type(X) :', type(X))\n",
    "print('type(dummy_y) :',type(dummy_y))"
   ]
  },
  {
   "cell_type": "code",
   "execution_count": 12,
   "id": "5144824e",
   "metadata": {},
   "outputs": [],
   "source": [
    "# X_train, X_test, y_train, y_test = train_test_split(X, dummy_y, test_size=0.33, random_state=seed)"
   ]
  },
  {
   "cell_type": "code",
   "execution_count": 13,
   "id": "fe48f5d7",
   "metadata": {},
   "outputs": [],
   "source": [
    "# creating the model\n",
    "def create_baseline_model():\n",
    "    model = Sequential()\n",
    "    model.add(Dense(units=8, input_dim=4, activation='relu', kernel_initializer='uniform',name='Hidden-Layer-1'))\n",
    "    model.add(Dense(units=3, activation='softmax', kernel_initializer='uniform', name='Output-Layer'))\n",
    "    # compile the model\n",
    "    model.compile(optimizer='adam', loss='categorical_crossentropy', metrics=['accuracy'])\n",
    "    return model"
   ]
  },
  {
   "cell_type": "code",
   "execution_count": 14,
   "id": "fee22890",
   "metadata": {},
   "outputs": [],
   "source": [
    "# model = create_baseline_model()"
   ]
  },
  {
   "cell_type": "code",
   "execution_count": 15,
   "id": "7b4c4c1e",
   "metadata": {},
   "outputs": [],
   "source": [
    "# fitting the model with auto validation\n",
    "\n",
    "# model.fit(X_train, y_train, validation_data=(X_test, y_test), epochs=100, batch_size=10, verbose=1)"
   ]
  },
  {
   "cell_type": "code",
   "execution_count": 16,
   "id": "73143d54",
   "metadata": {},
   "outputs": [],
   "source": [
    "# summary of the model\n",
    "\n",
    "# model.summary()"
   ]
  },
  {
   "cell_type": "markdown",
   "id": "9c0e716d",
   "metadata": {},
   "source": [
    "## Manual k-Fold Cross Validation - Evaluating using sklearn"
   ]
  },
  {
   "cell_type": "code",
   "execution_count": 17,
   "id": "35d28853",
   "metadata": {},
   "outputs": [],
   "source": [
    "estimator = KerasClassifier(build_fn= create_baseline_model, epochs=50, batch_size=5, verbose=1)"
   ]
  },
  {
   "cell_type": "code",
   "execution_count": 18,
   "id": "65f1acf8",
   "metadata": {},
   "outputs": [],
   "source": [
    "# defining 10-fold cross validation test harness\n",
    "\n",
    "kfold = StratifiedKFold(n_splits=10, shuffle=False, random_state=seed)\n"
   ]
  },
  {
   "cell_type": "code",
   "execution_count": 19,
   "id": "b32e24fc",
   "metadata": {},
   "outputs": [
    {
     "name": "stdout",
     "output_type": "stream",
     "text": [
      "Epoch 1/200\n",
      "Epoch 1/200\n"
     ]
    },
    {
     "name": "stderr",
     "output_type": "stream",
     "text": [
      "C:\\ProgramData\\Anaconda3\\envs\\tf-gpu-26\\lib\\site-packages\\sklearn\\model_selection\\_validation.py:615: FitFailedWarning: Estimator fit failed. The score on this train-test partition for these parameters will be set to nan. Details: \n",
      "Traceback (most recent call last):\n",
      "  File \"C:\\ProgramData\\Anaconda3\\envs\\tf-gpu-26\\lib\\site-packages\\sklearn\\model_selection\\_validation.py\", line 598, in _fit_and_score\n",
      "    estimator.fit(X_train, y_train, **fit_params)\n",
      "  File \"C:\\ProgramData\\Anaconda3\\envs\\tf-gpu-26\\lib\\site-packages\\keras\\wrappers\\scikit_learn.py\", line 219, in fit\n",
      "    return super(KerasClassifier, self).fit(x, y, **kwargs)\n",
      "  File \"C:\\ProgramData\\Anaconda3\\envs\\tf-gpu-26\\lib\\site-packages\\keras\\wrappers\\scikit_learn.py\", line 162, in fit\n",
      "    history = self.model.fit(x, y, **fit_args)\n",
      "  File \"C:\\ProgramData\\Anaconda3\\envs\\tf-gpu-26\\lib\\site-packages\\keras\\engine\\training.py\", line 1184, in fit\n",
      "    tmp_logs = self.train_function(iterator)\n",
      "  File \"C:\\ProgramData\\Anaconda3\\envs\\tf-gpu-26\\lib\\site-packages\\tensorflow\\python\\eager\\def_function.py\", line 885, in __call__\n",
      "    result = self._call(*args, **kwds)\n",
      "  File \"C:\\ProgramData\\Anaconda3\\envs\\tf-gpu-26\\lib\\site-packages\\tensorflow\\python\\eager\\def_function.py\", line 933, in _call\n",
      "    self._initialize(args, kwds, add_initializers_to=initializers)\n",
      "  File \"C:\\ProgramData\\Anaconda3\\envs\\tf-gpu-26\\lib\\site-packages\\tensorflow\\python\\eager\\def_function.py\", line 759, in _initialize\n",
      "    self._stateful_fn._get_concrete_function_internal_garbage_collected(  # pylint: disable=protected-access\n",
      "  File \"C:\\ProgramData\\Anaconda3\\envs\\tf-gpu-26\\lib\\site-packages\\tensorflow\\python\\eager\\function.py\", line 3066, in _get_concrete_function_internal_garbage_collected\n",
      "    graph_function, _ = self._maybe_define_function(args, kwargs)\n",
      "  File \"C:\\ProgramData\\Anaconda3\\envs\\tf-gpu-26\\lib\\site-packages\\tensorflow\\python\\eager\\function.py\", line 3463, in _maybe_define_function\n",
      "    graph_function = self._create_graph_function(args, kwargs)\n",
      "  File \"C:\\ProgramData\\Anaconda3\\envs\\tf-gpu-26\\lib\\site-packages\\tensorflow\\python\\eager\\function.py\", line 3298, in _create_graph_function\n",
      "    func_graph_module.func_graph_from_py_func(\n",
      "  File \"C:\\ProgramData\\Anaconda3\\envs\\tf-gpu-26\\lib\\site-packages\\tensorflow\\python\\framework\\func_graph.py\", line 1007, in func_graph_from_py_func\n",
      "    func_outputs = python_func(*func_args, **func_kwargs)\n",
      "  File \"C:\\ProgramData\\Anaconda3\\envs\\tf-gpu-26\\lib\\site-packages\\tensorflow\\python\\eager\\def_function.py\", line 668, in wrapped_fn\n",
      "    out = weak_wrapped_fn().__wrapped__(*args, **kwds)\n",
      "  File \"C:\\ProgramData\\Anaconda3\\envs\\tf-gpu-26\\lib\\site-packages\\tensorflow\\python\\framework\\func_graph.py\", line 994, in wrapper\n",
      "    raise e.ag_error_metadata.to_exception(e)\n",
      "ValueError: in user code:\n",
      "\n",
      "    C:\\ProgramData\\Anaconda3\\envs\\tf-gpu-26\\lib\\site-packages\\keras\\engine\\training.py:853 train_function  *\n",
      "        return step_function(self, iterator)\n",
      "    C:\\ProgramData\\Anaconda3\\envs\\tf-gpu-26\\lib\\site-packages\\keras\\engine\\training.py:842 step_function  **\n",
      "        outputs = model.distribute_strategy.run(run_step, args=(data,))\n",
      "    C:\\ProgramData\\Anaconda3\\envs\\tf-gpu-26\\lib\\site-packages\\tensorflow\\python\\distribute\\distribute_lib.py:1286 run\n",
      "        return self._extended.call_for_each_replica(fn, args=args, kwargs=kwargs)\n",
      "    C:\\ProgramData\\Anaconda3\\envs\\tf-gpu-26\\lib\\site-packages\\tensorflow\\python\\distribute\\distribute_lib.py:2849 call_for_each_replica\n",
      "        return self._call_for_each_replica(fn, args, kwargs)\n",
      "    C:\\ProgramData\\Anaconda3\\envs\\tf-gpu-26\\lib\\site-packages\\tensorflow\\python\\distribute\\distribute_lib.py:3632 _call_for_each_replica\n",
      "        return fn(*args, **kwargs)\n",
      "    C:\\ProgramData\\Anaconda3\\envs\\tf-gpu-26\\lib\\site-packages\\keras\\engine\\training.py:835 run_step  **\n",
      "        outputs = model.train_step(data)\n",
      "    C:\\ProgramData\\Anaconda3\\envs\\tf-gpu-26\\lib\\site-packages\\keras\\engine\\training.py:788 train_step\n",
      "        loss = self.compiled_loss(\n",
      "    C:\\ProgramData\\Anaconda3\\envs\\tf-gpu-26\\lib\\site-packages\\keras\\engine\\compile_utils.py:201 __call__\n",
      "        loss_value = loss_obj(y_t, y_p, sample_weight=sw)\n",
      "    C:\\ProgramData\\Anaconda3\\envs\\tf-gpu-26\\lib\\site-packages\\keras\\losses.py:141 __call__\n",
      "        losses = call_fn(y_true, y_pred)\n",
      "    C:\\ProgramData\\Anaconda3\\envs\\tf-gpu-26\\lib\\site-packages\\keras\\losses.py:245 call  **\n",
      "        return ag_fn(y_true, y_pred, **self._fn_kwargs)\n",
      "    C:\\ProgramData\\Anaconda3\\envs\\tf-gpu-26\\lib\\site-packages\\tensorflow\\python\\util\\dispatch.py:206 wrapper\n",
      "        return target(*args, **kwargs)\n",
      "    C:\\ProgramData\\Anaconda3\\envs\\tf-gpu-26\\lib\\site-packages\\keras\\losses.py:1665 categorical_crossentropy\n",
      "        return backend.categorical_crossentropy(\n",
      "    C:\\ProgramData\\Anaconda3\\envs\\tf-gpu-26\\lib\\site-packages\\tensorflow\\python\\util\\dispatch.py:206 wrapper\n",
      "        return target(*args, **kwargs)\n",
      "    C:\\ProgramData\\Anaconda3\\envs\\tf-gpu-26\\lib\\site-packages\\keras\\backend.py:4839 categorical_crossentropy\n",
      "        target.shape.assert_is_compatible_with(output.shape)\n",
      "    C:\\ProgramData\\Anaconda3\\envs\\tf-gpu-26\\lib\\site-packages\\tensorflow\\python\\framework\\tensor_shape.py:1161 assert_is_compatible_with\n",
      "        raise ValueError(\"Shapes %s and %s are incompatible\" % (self, other))\n",
      "\n",
      "    ValueError: Shapes (5, 22) and (5, 3) are incompatible\n",
      "\n",
      "\n",
      "  warnings.warn(\"Estimator fit failed. The score on this train-test\"\n",
      "C:\\ProgramData\\Anaconda3\\envs\\tf-gpu-26\\lib\\site-packages\\sklearn\\model_selection\\_validation.py:615: FitFailedWarning: Estimator fit failed. The score on this train-test partition for these parameters will be set to nan. Details: \n",
      "Traceback (most recent call last):\n",
      "  File \"C:\\ProgramData\\Anaconda3\\envs\\tf-gpu-26\\lib\\site-packages\\sklearn\\model_selection\\_validation.py\", line 598, in _fit_and_score\n",
      "    estimator.fit(X_train, y_train, **fit_params)\n",
      "  File \"C:\\ProgramData\\Anaconda3\\envs\\tf-gpu-26\\lib\\site-packages\\keras\\wrappers\\scikit_learn.py\", line 219, in fit\n",
      "    return super(KerasClassifier, self).fit(x, y, **kwargs)\n",
      "  File \"C:\\ProgramData\\Anaconda3\\envs\\tf-gpu-26\\lib\\site-packages\\keras\\wrappers\\scikit_learn.py\", line 162, in fit\n",
      "    history = self.model.fit(x, y, **fit_args)\n",
      "  File \"C:\\ProgramData\\Anaconda3\\envs\\tf-gpu-26\\lib\\site-packages\\keras\\engine\\training.py\", line 1184, in fit\n",
      "    tmp_logs = self.train_function(iterator)\n",
      "  File \"C:\\ProgramData\\Anaconda3\\envs\\tf-gpu-26\\lib\\site-packages\\tensorflow\\python\\eager\\def_function.py\", line 885, in __call__\n",
      "    result = self._call(*args, **kwds)\n",
      "  File \"C:\\ProgramData\\Anaconda3\\envs\\tf-gpu-26\\lib\\site-packages\\tensorflow\\python\\eager\\def_function.py\", line 933, in _call\n",
      "    self._initialize(args, kwds, add_initializers_to=initializers)\n",
      "  File \"C:\\ProgramData\\Anaconda3\\envs\\tf-gpu-26\\lib\\site-packages\\tensorflow\\python\\eager\\def_function.py\", line 759, in _initialize\n",
      "    self._stateful_fn._get_concrete_function_internal_garbage_collected(  # pylint: disable=protected-access\n",
      "  File \"C:\\ProgramData\\Anaconda3\\envs\\tf-gpu-26\\lib\\site-packages\\tensorflow\\python\\eager\\function.py\", line 3066, in _get_concrete_function_internal_garbage_collected\n",
      "    graph_function, _ = self._maybe_define_function(args, kwargs)\n",
      "  File \"C:\\ProgramData\\Anaconda3\\envs\\tf-gpu-26\\lib\\site-packages\\tensorflow\\python\\eager\\function.py\", line 3463, in _maybe_define_function\n",
      "    graph_function = self._create_graph_function(args, kwargs)\n",
      "  File \"C:\\ProgramData\\Anaconda3\\envs\\tf-gpu-26\\lib\\site-packages\\tensorflow\\python\\eager\\function.py\", line 3298, in _create_graph_function\n",
      "    func_graph_module.func_graph_from_py_func(\n",
      "  File \"C:\\ProgramData\\Anaconda3\\envs\\tf-gpu-26\\lib\\site-packages\\tensorflow\\python\\framework\\func_graph.py\", line 1007, in func_graph_from_py_func\n",
      "    func_outputs = python_func(*func_args, **func_kwargs)\n",
      "  File \"C:\\ProgramData\\Anaconda3\\envs\\tf-gpu-26\\lib\\site-packages\\tensorflow\\python\\eager\\def_function.py\", line 668, in wrapped_fn\n",
      "    out = weak_wrapped_fn().__wrapped__(*args, **kwds)\n",
      "  File \"C:\\ProgramData\\Anaconda3\\envs\\tf-gpu-26\\lib\\site-packages\\tensorflow\\python\\framework\\func_graph.py\", line 994, in wrapper\n",
      "    raise e.ag_error_metadata.to_exception(e)\n",
      "ValueError: in user code:\n",
      "\n",
      "    C:\\ProgramData\\Anaconda3\\envs\\tf-gpu-26\\lib\\site-packages\\keras\\engine\\training.py:853 train_function  *\n",
      "        return step_function(self, iterator)\n",
      "    C:\\ProgramData\\Anaconda3\\envs\\tf-gpu-26\\lib\\site-packages\\keras\\engine\\training.py:842 step_function  **\n",
      "        outputs = model.distribute_strategy.run(run_step, args=(data,))\n",
      "    C:\\ProgramData\\Anaconda3\\envs\\tf-gpu-26\\lib\\site-packages\\tensorflow\\python\\distribute\\distribute_lib.py:1286 run\n",
      "        return self._extended.call_for_each_replica(fn, args=args, kwargs=kwargs)\n",
      "    C:\\ProgramData\\Anaconda3\\envs\\tf-gpu-26\\lib\\site-packages\\tensorflow\\python\\distribute\\distribute_lib.py:2849 call_for_each_replica\n",
      "        return self._call_for_each_replica(fn, args, kwargs)\n",
      "    C:\\ProgramData\\Anaconda3\\envs\\tf-gpu-26\\lib\\site-packages\\tensorflow\\python\\distribute\\distribute_lib.py:3632 _call_for_each_replica\n",
      "        return fn(*args, **kwargs)\n",
      "    C:\\ProgramData\\Anaconda3\\envs\\tf-gpu-26\\lib\\site-packages\\keras\\engine\\training.py:835 run_step  **\n",
      "        outputs = model.train_step(data)\n",
      "    C:\\ProgramData\\Anaconda3\\envs\\tf-gpu-26\\lib\\site-packages\\keras\\engine\\training.py:788 train_step\n",
      "        loss = self.compiled_loss(\n",
      "    C:\\ProgramData\\Anaconda3\\envs\\tf-gpu-26\\lib\\site-packages\\keras\\engine\\compile_utils.py:201 __call__\n",
      "        loss_value = loss_obj(y_t, y_p, sample_weight=sw)\n",
      "    C:\\ProgramData\\Anaconda3\\envs\\tf-gpu-26\\lib\\site-packages\\keras\\losses.py:141 __call__\n",
      "        losses = call_fn(y_true, y_pred)\n",
      "    C:\\ProgramData\\Anaconda3\\envs\\tf-gpu-26\\lib\\site-packages\\keras\\losses.py:245 call  **\n",
      "        return ag_fn(y_true, y_pred, **self._fn_kwargs)\n",
      "    C:\\ProgramData\\Anaconda3\\envs\\tf-gpu-26\\lib\\site-packages\\tensorflow\\python\\util\\dispatch.py:206 wrapper\n",
      "        return target(*args, **kwargs)\n",
      "    C:\\ProgramData\\Anaconda3\\envs\\tf-gpu-26\\lib\\site-packages\\keras\\losses.py:1665 categorical_crossentropy\n",
      "        return backend.categorical_crossentropy(\n",
      "    C:\\ProgramData\\Anaconda3\\envs\\tf-gpu-26\\lib\\site-packages\\tensorflow\\python\\util\\dispatch.py:206 wrapper\n",
      "        return target(*args, **kwargs)\n",
      "    C:\\ProgramData\\Anaconda3\\envs\\tf-gpu-26\\lib\\site-packages\\keras\\backend.py:4839 categorical_crossentropy\n",
      "        target.shape.assert_is_compatible_with(output.shape)\n",
      "    C:\\ProgramData\\Anaconda3\\envs\\tf-gpu-26\\lib\\site-packages\\tensorflow\\python\\framework\\tensor_shape.py:1161 assert_is_compatible_with\n",
      "        raise ValueError(\"Shapes %s and %s are incompatible\" % (self, other))\n",
      "\n",
      "    ValueError: Shapes (5, 22) and (5, 3) are incompatible\n",
      "\n",
      "\n",
      "  warnings.warn(\"Estimator fit failed. The score on this train-test\"\n",
      "C:\\ProgramData\\Anaconda3\\envs\\tf-gpu-26\\lib\\site-packages\\sklearn\\model_selection\\_validation.py:615: FitFailedWarning: Estimator fit failed. The score on this train-test partition for these parameters will be set to nan. Details: \n",
      "Traceback (most recent call last):\n",
      "  File \"C:\\ProgramData\\Anaconda3\\envs\\tf-gpu-26\\lib\\site-packages\\sklearn\\model_selection\\_validation.py\", line 598, in _fit_and_score\n",
      "    estimator.fit(X_train, y_train, **fit_params)\n",
      "  File \"C:\\ProgramData\\Anaconda3\\envs\\tf-gpu-26\\lib\\site-packages\\keras\\wrappers\\scikit_learn.py\", line 219, in fit\n",
      "    return super(KerasClassifier, self).fit(x, y, **kwargs)\n",
      "  File \"C:\\ProgramData\\Anaconda3\\envs\\tf-gpu-26\\lib\\site-packages\\keras\\wrappers\\scikit_learn.py\", line 162, in fit\n",
      "    history = self.model.fit(x, y, **fit_args)\n",
      "  File \"C:\\ProgramData\\Anaconda3\\envs\\tf-gpu-26\\lib\\site-packages\\keras\\engine\\training.py\", line 1184, in fit\n",
      "    tmp_logs = self.train_function(iterator)\n",
      "  File \"C:\\ProgramData\\Anaconda3\\envs\\tf-gpu-26\\lib\\site-packages\\tensorflow\\python\\eager\\def_function.py\", line 885, in __call__\n",
      "    result = self._call(*args, **kwds)\n",
      "  File \"C:\\ProgramData\\Anaconda3\\envs\\tf-gpu-26\\lib\\site-packages\\tensorflow\\python\\eager\\def_function.py\", line 933, in _call\n",
      "    self._initialize(args, kwds, add_initializers_to=initializers)\n",
      "  File \"C:\\ProgramData\\Anaconda3\\envs\\tf-gpu-26\\lib\\site-packages\\tensorflow\\python\\eager\\def_function.py\", line 759, in _initialize\n",
      "    self._stateful_fn._get_concrete_function_internal_garbage_collected(  # pylint: disable=protected-access\n",
      "  File \"C:\\ProgramData\\Anaconda3\\envs\\tf-gpu-26\\lib\\site-packages\\tensorflow\\python\\eager\\function.py\", line 3066, in _get_concrete_function_internal_garbage_collected\n",
      "    graph_function, _ = self._maybe_define_function(args, kwargs)\n",
      "  File \"C:\\ProgramData\\Anaconda3\\envs\\tf-gpu-26\\lib\\site-packages\\tensorflow\\python\\eager\\function.py\", line 3463, in _maybe_define_function\n",
      "    graph_function = self._create_graph_function(args, kwargs)\n",
      "  File \"C:\\ProgramData\\Anaconda3\\envs\\tf-gpu-26\\lib\\site-packages\\tensorflow\\python\\eager\\function.py\", line 3298, in _create_graph_function\n",
      "    func_graph_module.func_graph_from_py_func(\n",
      "  File \"C:\\ProgramData\\Anaconda3\\envs\\tf-gpu-26\\lib\\site-packages\\tensorflow\\python\\framework\\func_graph.py\", line 1007, in func_graph_from_py_func\n",
      "    func_outputs = python_func(*func_args, **func_kwargs)\n",
      "  File \"C:\\ProgramData\\Anaconda3\\envs\\tf-gpu-26\\lib\\site-packages\\tensorflow\\python\\eager\\def_function.py\", line 668, in wrapped_fn\n",
      "    out = weak_wrapped_fn().__wrapped__(*args, **kwds)\n",
      "  File \"C:\\ProgramData\\Anaconda3\\envs\\tf-gpu-26\\lib\\site-packages\\tensorflow\\python\\framework\\func_graph.py\", line 994, in wrapper\n",
      "    raise e.ag_error_metadata.to_exception(e)\n",
      "ValueError: in user code:\n",
      "\n",
      "    C:\\ProgramData\\Anaconda3\\envs\\tf-gpu-26\\lib\\site-packages\\keras\\engine\\training.py:853 train_function  *\n",
      "        return step_function(self, iterator)\n",
      "    C:\\ProgramData\\Anaconda3\\envs\\tf-gpu-26\\lib\\site-packages\\keras\\engine\\training.py:842 step_function  **\n",
      "        outputs = model.distribute_strategy.run(run_step, args=(data,))\n",
      "    C:\\ProgramData\\Anaconda3\\envs\\tf-gpu-26\\lib\\site-packages\\tensorflow\\python\\distribute\\distribute_lib.py:1286 run\n",
      "        return self._extended.call_for_each_replica(fn, args=args, kwargs=kwargs)\n",
      "    C:\\ProgramData\\Anaconda3\\envs\\tf-gpu-26\\lib\\site-packages\\tensorflow\\python\\distribute\\distribute_lib.py:2849 call_for_each_replica\n",
      "        return self._call_for_each_replica(fn, args, kwargs)\n",
      "    C:\\ProgramData\\Anaconda3\\envs\\tf-gpu-26\\lib\\site-packages\\tensorflow\\python\\distribute\\distribute_lib.py:3632 _call_for_each_replica\n",
      "        return fn(*args, **kwargs)\n",
      "    C:\\ProgramData\\Anaconda3\\envs\\tf-gpu-26\\lib\\site-packages\\keras\\engine\\training.py:835 run_step  **\n",
      "        outputs = model.train_step(data)\n",
      "    C:\\ProgramData\\Anaconda3\\envs\\tf-gpu-26\\lib\\site-packages\\keras\\engine\\training.py:788 train_step\n",
      "        loss = self.compiled_loss(\n",
      "    C:\\ProgramData\\Anaconda3\\envs\\tf-gpu-26\\lib\\site-packages\\keras\\engine\\compile_utils.py:201 __call__\n",
      "        loss_value = loss_obj(y_t, y_p, sample_weight=sw)\n",
      "    C:\\ProgramData\\Anaconda3\\envs\\tf-gpu-26\\lib\\site-packages\\keras\\losses.py:141 __call__\n",
      "        losses = call_fn(y_true, y_pred)\n",
      "    C:\\ProgramData\\Anaconda3\\envs\\tf-gpu-26\\lib\\site-packages\\keras\\losses.py:245 call  **\n",
      "        return ag_fn(y_true, y_pred, **self._fn_kwargs)\n",
      "    C:\\ProgramData\\Anaconda3\\envs\\tf-gpu-26\\lib\\site-packages\\tensorflow\\python\\util\\dispatch.py:206 wrapper\n",
      "        return target(*args, **kwargs)\n",
      "    C:\\ProgramData\\Anaconda3\\envs\\tf-gpu-26\\lib\\site-packages\\keras\\losses.py:1665 categorical_crossentropy\n",
      "        return backend.categorical_crossentropy(\n",
      "    C:\\ProgramData\\Anaconda3\\envs\\tf-gpu-26\\lib\\site-packages\\tensorflow\\python\\util\\dispatch.py:206 wrapper\n",
      "        return target(*args, **kwargs)\n",
      "    C:\\ProgramData\\Anaconda3\\envs\\tf-gpu-26\\lib\\site-packages\\keras\\backend.py:4839 categorical_crossentropy\n",
      "        target.shape.assert_is_compatible_with(output.shape)\n",
      "    C:\\ProgramData\\Anaconda3\\envs\\tf-gpu-26\\lib\\site-packages\\tensorflow\\python\\framework\\tensor_shape.py:1161 assert_is_compatible_with\n",
      "        raise ValueError(\"Shapes %s and %s are incompatible\" % (self, other))\n",
      "\n",
      "    ValueError: Shapes (5, 22) and (5, 3) are incompatible\n",
      "\n",
      "\n",
      "  warnings.warn(\"Estimator fit failed. The score on this train-test\"\n"
     ]
    },
    {
     "name": "stdout",
     "output_type": "stream",
     "text": [
      "Epoch 1/200\n",
      "Epoch 1/200\n",
      "Epoch 1/200\n"
     ]
    },
    {
     "name": "stderr",
     "output_type": "stream",
     "text": [
      "C:\\ProgramData\\Anaconda3\\envs\\tf-gpu-26\\lib\\site-packages\\sklearn\\model_selection\\_validation.py:615: FitFailedWarning: Estimator fit failed. The score on this train-test partition for these parameters will be set to nan. Details: \n",
      "Traceback (most recent call last):\n",
      "  File \"C:\\ProgramData\\Anaconda3\\envs\\tf-gpu-26\\lib\\site-packages\\sklearn\\model_selection\\_validation.py\", line 598, in _fit_and_score\n",
      "    estimator.fit(X_train, y_train, **fit_params)\n",
      "  File \"C:\\ProgramData\\Anaconda3\\envs\\tf-gpu-26\\lib\\site-packages\\keras\\wrappers\\scikit_learn.py\", line 219, in fit\n",
      "    return super(KerasClassifier, self).fit(x, y, **kwargs)\n",
      "  File \"C:\\ProgramData\\Anaconda3\\envs\\tf-gpu-26\\lib\\site-packages\\keras\\wrappers\\scikit_learn.py\", line 162, in fit\n",
      "    history = self.model.fit(x, y, **fit_args)\n",
      "  File \"C:\\ProgramData\\Anaconda3\\envs\\tf-gpu-26\\lib\\site-packages\\keras\\engine\\training.py\", line 1184, in fit\n",
      "    tmp_logs = self.train_function(iterator)\n",
      "  File \"C:\\ProgramData\\Anaconda3\\envs\\tf-gpu-26\\lib\\site-packages\\tensorflow\\python\\eager\\def_function.py\", line 885, in __call__\n",
      "    result = self._call(*args, **kwds)\n",
      "  File \"C:\\ProgramData\\Anaconda3\\envs\\tf-gpu-26\\lib\\site-packages\\tensorflow\\python\\eager\\def_function.py\", line 933, in _call\n",
      "    self._initialize(args, kwds, add_initializers_to=initializers)\n",
      "  File \"C:\\ProgramData\\Anaconda3\\envs\\tf-gpu-26\\lib\\site-packages\\tensorflow\\python\\eager\\def_function.py\", line 759, in _initialize\n",
      "    self._stateful_fn._get_concrete_function_internal_garbage_collected(  # pylint: disable=protected-access\n",
      "  File \"C:\\ProgramData\\Anaconda3\\envs\\tf-gpu-26\\lib\\site-packages\\tensorflow\\python\\eager\\function.py\", line 3066, in _get_concrete_function_internal_garbage_collected\n",
      "    graph_function, _ = self._maybe_define_function(args, kwargs)\n",
      "  File \"C:\\ProgramData\\Anaconda3\\envs\\tf-gpu-26\\lib\\site-packages\\tensorflow\\python\\eager\\function.py\", line 3463, in _maybe_define_function\n",
      "    graph_function = self._create_graph_function(args, kwargs)\n",
      "  File \"C:\\ProgramData\\Anaconda3\\envs\\tf-gpu-26\\lib\\site-packages\\tensorflow\\python\\eager\\function.py\", line 3298, in _create_graph_function\n",
      "    func_graph_module.func_graph_from_py_func(\n",
      "  File \"C:\\ProgramData\\Anaconda3\\envs\\tf-gpu-26\\lib\\site-packages\\tensorflow\\python\\framework\\func_graph.py\", line 1007, in func_graph_from_py_func\n",
      "    func_outputs = python_func(*func_args, **func_kwargs)\n",
      "  File \"C:\\ProgramData\\Anaconda3\\envs\\tf-gpu-26\\lib\\site-packages\\tensorflow\\python\\eager\\def_function.py\", line 668, in wrapped_fn\n",
      "    out = weak_wrapped_fn().__wrapped__(*args, **kwds)\n",
      "  File \"C:\\ProgramData\\Anaconda3\\envs\\tf-gpu-26\\lib\\site-packages\\tensorflow\\python\\framework\\func_graph.py\", line 994, in wrapper\n",
      "    raise e.ag_error_metadata.to_exception(e)\n",
      "ValueError: in user code:\n",
      "\n",
      "    C:\\ProgramData\\Anaconda3\\envs\\tf-gpu-26\\lib\\site-packages\\keras\\engine\\training.py:853 train_function  *\n",
      "        return step_function(self, iterator)\n",
      "    C:\\ProgramData\\Anaconda3\\envs\\tf-gpu-26\\lib\\site-packages\\keras\\engine\\training.py:842 step_function  **\n",
      "        outputs = model.distribute_strategy.run(run_step, args=(data,))\n",
      "    C:\\ProgramData\\Anaconda3\\envs\\tf-gpu-26\\lib\\site-packages\\tensorflow\\python\\distribute\\distribute_lib.py:1286 run\n",
      "        return self._extended.call_for_each_replica(fn, args=args, kwargs=kwargs)\n",
      "    C:\\ProgramData\\Anaconda3\\envs\\tf-gpu-26\\lib\\site-packages\\tensorflow\\python\\distribute\\distribute_lib.py:2849 call_for_each_replica\n",
      "        return self._call_for_each_replica(fn, args, kwargs)\n",
      "    C:\\ProgramData\\Anaconda3\\envs\\tf-gpu-26\\lib\\site-packages\\tensorflow\\python\\distribute\\distribute_lib.py:3632 _call_for_each_replica\n",
      "        return fn(*args, **kwargs)\n",
      "    C:\\ProgramData\\Anaconda3\\envs\\tf-gpu-26\\lib\\site-packages\\keras\\engine\\training.py:835 run_step  **\n",
      "        outputs = model.train_step(data)\n",
      "    C:\\ProgramData\\Anaconda3\\envs\\tf-gpu-26\\lib\\site-packages\\keras\\engine\\training.py:788 train_step\n",
      "        loss = self.compiled_loss(\n",
      "    C:\\ProgramData\\Anaconda3\\envs\\tf-gpu-26\\lib\\site-packages\\keras\\engine\\compile_utils.py:201 __call__\n",
      "        loss_value = loss_obj(y_t, y_p, sample_weight=sw)\n",
      "    C:\\ProgramData\\Anaconda3\\envs\\tf-gpu-26\\lib\\site-packages\\keras\\losses.py:141 __call__\n",
      "        losses = call_fn(y_true, y_pred)\n",
      "    C:\\ProgramData\\Anaconda3\\envs\\tf-gpu-26\\lib\\site-packages\\keras\\losses.py:245 call  **\n",
      "        return ag_fn(y_true, y_pred, **self._fn_kwargs)\n",
      "    C:\\ProgramData\\Anaconda3\\envs\\tf-gpu-26\\lib\\site-packages\\tensorflow\\python\\util\\dispatch.py:206 wrapper\n",
      "        return target(*args, **kwargs)\n",
      "    C:\\ProgramData\\Anaconda3\\envs\\tf-gpu-26\\lib\\site-packages\\keras\\losses.py:1665 categorical_crossentropy\n",
      "        return backend.categorical_crossentropy(\n",
      "    C:\\ProgramData\\Anaconda3\\envs\\tf-gpu-26\\lib\\site-packages\\tensorflow\\python\\util\\dispatch.py:206 wrapper\n",
      "        return target(*args, **kwargs)\n",
      "    C:\\ProgramData\\Anaconda3\\envs\\tf-gpu-26\\lib\\site-packages\\keras\\backend.py:4839 categorical_crossentropy\n",
      "        target.shape.assert_is_compatible_with(output.shape)\n",
      "    C:\\ProgramData\\Anaconda3\\envs\\tf-gpu-26\\lib\\site-packages\\tensorflow\\python\\framework\\tensor_shape.py:1161 assert_is_compatible_with\n",
      "        raise ValueError(\"Shapes %s and %s are incompatible\" % (self, other))\n",
      "\n",
      "    ValueError: Shapes (5, 22) and (5, 3) are incompatible\n",
      "\n",
      "\n",
      "  warnings.warn(\"Estimator fit failed. The score on this train-test\"\n",
      "C:\\ProgramData\\Anaconda3\\envs\\tf-gpu-26\\lib\\site-packages\\sklearn\\model_selection\\_validation.py:615: FitFailedWarning: Estimator fit failed. The score on this train-test partition for these parameters will be set to nan. Details: \n",
      "Traceback (most recent call last):\n",
      "  File \"C:\\ProgramData\\Anaconda3\\envs\\tf-gpu-26\\lib\\site-packages\\sklearn\\model_selection\\_validation.py\", line 598, in _fit_and_score\n",
      "    estimator.fit(X_train, y_train, **fit_params)\n",
      "  File \"C:\\ProgramData\\Anaconda3\\envs\\tf-gpu-26\\lib\\site-packages\\keras\\wrappers\\scikit_learn.py\", line 219, in fit\n",
      "    return super(KerasClassifier, self).fit(x, y, **kwargs)\n",
      "  File \"C:\\ProgramData\\Anaconda3\\envs\\tf-gpu-26\\lib\\site-packages\\keras\\wrappers\\scikit_learn.py\", line 162, in fit\n",
      "    history = self.model.fit(x, y, **fit_args)\n",
      "  File \"C:\\ProgramData\\Anaconda3\\envs\\tf-gpu-26\\lib\\site-packages\\keras\\engine\\training.py\", line 1184, in fit\n",
      "    tmp_logs = self.train_function(iterator)\n",
      "  File \"C:\\ProgramData\\Anaconda3\\envs\\tf-gpu-26\\lib\\site-packages\\tensorflow\\python\\eager\\def_function.py\", line 885, in __call__\n",
      "    result = self._call(*args, **kwds)\n",
      "  File \"C:\\ProgramData\\Anaconda3\\envs\\tf-gpu-26\\lib\\site-packages\\tensorflow\\python\\eager\\def_function.py\", line 933, in _call\n",
      "    self._initialize(args, kwds, add_initializers_to=initializers)\n",
      "  File \"C:\\ProgramData\\Anaconda3\\envs\\tf-gpu-26\\lib\\site-packages\\tensorflow\\python\\eager\\def_function.py\", line 759, in _initialize\n",
      "    self._stateful_fn._get_concrete_function_internal_garbage_collected(  # pylint: disable=protected-access\n",
      "  File \"C:\\ProgramData\\Anaconda3\\envs\\tf-gpu-26\\lib\\site-packages\\tensorflow\\python\\eager\\function.py\", line 3066, in _get_concrete_function_internal_garbage_collected\n",
      "    graph_function, _ = self._maybe_define_function(args, kwargs)\n",
      "  File \"C:\\ProgramData\\Anaconda3\\envs\\tf-gpu-26\\lib\\site-packages\\tensorflow\\python\\eager\\function.py\", line 3463, in _maybe_define_function\n",
      "    graph_function = self._create_graph_function(args, kwargs)\n",
      "  File \"C:\\ProgramData\\Anaconda3\\envs\\tf-gpu-26\\lib\\site-packages\\tensorflow\\python\\eager\\function.py\", line 3298, in _create_graph_function\n",
      "    func_graph_module.func_graph_from_py_func(\n",
      "  File \"C:\\ProgramData\\Anaconda3\\envs\\tf-gpu-26\\lib\\site-packages\\tensorflow\\python\\framework\\func_graph.py\", line 1007, in func_graph_from_py_func\n",
      "    func_outputs = python_func(*func_args, **func_kwargs)\n",
      "  File \"C:\\ProgramData\\Anaconda3\\envs\\tf-gpu-26\\lib\\site-packages\\tensorflow\\python\\eager\\def_function.py\", line 668, in wrapped_fn\n",
      "    out = weak_wrapped_fn().__wrapped__(*args, **kwds)\n",
      "  File \"C:\\ProgramData\\Anaconda3\\envs\\tf-gpu-26\\lib\\site-packages\\tensorflow\\python\\framework\\func_graph.py\", line 994, in wrapper\n",
      "    raise e.ag_error_metadata.to_exception(e)\n",
      "ValueError: in user code:\n",
      "\n",
      "    C:\\ProgramData\\Anaconda3\\envs\\tf-gpu-26\\lib\\site-packages\\keras\\engine\\training.py:853 train_function  *\n",
      "        return step_function(self, iterator)\n",
      "    C:\\ProgramData\\Anaconda3\\envs\\tf-gpu-26\\lib\\site-packages\\keras\\engine\\training.py:842 step_function  **\n",
      "        outputs = model.distribute_strategy.run(run_step, args=(data,))\n",
      "    C:\\ProgramData\\Anaconda3\\envs\\tf-gpu-26\\lib\\site-packages\\tensorflow\\python\\distribute\\distribute_lib.py:1286 run\n",
      "        return self._extended.call_for_each_replica(fn, args=args, kwargs=kwargs)\n",
      "    C:\\ProgramData\\Anaconda3\\envs\\tf-gpu-26\\lib\\site-packages\\tensorflow\\python\\distribute\\distribute_lib.py:2849 call_for_each_replica\n",
      "        return self._call_for_each_replica(fn, args, kwargs)\n",
      "    C:\\ProgramData\\Anaconda3\\envs\\tf-gpu-26\\lib\\site-packages\\tensorflow\\python\\distribute\\distribute_lib.py:3632 _call_for_each_replica\n",
      "        return fn(*args, **kwargs)\n",
      "    C:\\ProgramData\\Anaconda3\\envs\\tf-gpu-26\\lib\\site-packages\\keras\\engine\\training.py:835 run_step  **\n",
      "        outputs = model.train_step(data)\n",
      "    C:\\ProgramData\\Anaconda3\\envs\\tf-gpu-26\\lib\\site-packages\\keras\\engine\\training.py:788 train_step\n",
      "        loss = self.compiled_loss(\n",
      "    C:\\ProgramData\\Anaconda3\\envs\\tf-gpu-26\\lib\\site-packages\\keras\\engine\\compile_utils.py:201 __call__\n",
      "        loss_value = loss_obj(y_t, y_p, sample_weight=sw)\n",
      "    C:\\ProgramData\\Anaconda3\\envs\\tf-gpu-26\\lib\\site-packages\\keras\\losses.py:141 __call__\n",
      "        losses = call_fn(y_true, y_pred)\n",
      "    C:\\ProgramData\\Anaconda3\\envs\\tf-gpu-26\\lib\\site-packages\\keras\\losses.py:245 call  **\n",
      "        return ag_fn(y_true, y_pred, **self._fn_kwargs)\n",
      "    C:\\ProgramData\\Anaconda3\\envs\\tf-gpu-26\\lib\\site-packages\\tensorflow\\python\\util\\dispatch.py:206 wrapper\n",
      "        return target(*args, **kwargs)\n",
      "    C:\\ProgramData\\Anaconda3\\envs\\tf-gpu-26\\lib\\site-packages\\keras\\losses.py:1665 categorical_crossentropy\n",
      "        return backend.categorical_crossentropy(\n",
      "    C:\\ProgramData\\Anaconda3\\envs\\tf-gpu-26\\lib\\site-packages\\tensorflow\\python\\util\\dispatch.py:206 wrapper\n",
      "        return target(*args, **kwargs)\n",
      "    C:\\ProgramData\\Anaconda3\\envs\\tf-gpu-26\\lib\\site-packages\\keras\\backend.py:4839 categorical_crossentropy\n",
      "        target.shape.assert_is_compatible_with(output.shape)\n",
      "    C:\\ProgramData\\Anaconda3\\envs\\tf-gpu-26\\lib\\site-packages\\tensorflow\\python\\framework\\tensor_shape.py:1161 assert_is_compatible_with\n",
      "        raise ValueError(\"Shapes %s and %s are incompatible\" % (self, other))\n",
      "\n",
      "    ValueError: Shapes (5, 22) and (5, 3) are incompatible\n",
      "\n",
      "\n",
      "  warnings.warn(\"Estimator fit failed. The score on this train-test\"\n"
     ]
    },
    {
     "name": "stdout",
     "output_type": "stream",
     "text": [
      "Epoch 1/200\n",
      "Epoch 1/200\n"
     ]
    },
    {
     "name": "stderr",
     "output_type": "stream",
     "text": [
      "C:\\ProgramData\\Anaconda3\\envs\\tf-gpu-26\\lib\\site-packages\\sklearn\\model_selection\\_validation.py:615: FitFailedWarning: Estimator fit failed. The score on this train-test partition for these parameters will be set to nan. Details: \n",
      "Traceback (most recent call last):\n",
      "  File \"C:\\ProgramData\\Anaconda3\\envs\\tf-gpu-26\\lib\\site-packages\\sklearn\\model_selection\\_validation.py\", line 598, in _fit_and_score\n",
      "    estimator.fit(X_train, y_train, **fit_params)\n",
      "  File \"C:\\ProgramData\\Anaconda3\\envs\\tf-gpu-26\\lib\\site-packages\\keras\\wrappers\\scikit_learn.py\", line 219, in fit\n",
      "    return super(KerasClassifier, self).fit(x, y, **kwargs)\n",
      "  File \"C:\\ProgramData\\Anaconda3\\envs\\tf-gpu-26\\lib\\site-packages\\keras\\wrappers\\scikit_learn.py\", line 162, in fit\n",
      "    history = self.model.fit(x, y, **fit_args)\n",
      "  File \"C:\\ProgramData\\Anaconda3\\envs\\tf-gpu-26\\lib\\site-packages\\keras\\engine\\training.py\", line 1184, in fit\n",
      "    tmp_logs = self.train_function(iterator)\n",
      "  File \"C:\\ProgramData\\Anaconda3\\envs\\tf-gpu-26\\lib\\site-packages\\tensorflow\\python\\eager\\def_function.py\", line 885, in __call__\n",
      "    result = self._call(*args, **kwds)\n",
      "  File \"C:\\ProgramData\\Anaconda3\\envs\\tf-gpu-26\\lib\\site-packages\\tensorflow\\python\\eager\\def_function.py\", line 933, in _call\n",
      "    self._initialize(args, kwds, add_initializers_to=initializers)\n",
      "  File \"C:\\ProgramData\\Anaconda3\\envs\\tf-gpu-26\\lib\\site-packages\\tensorflow\\python\\eager\\def_function.py\", line 759, in _initialize\n",
      "    self._stateful_fn._get_concrete_function_internal_garbage_collected(  # pylint: disable=protected-access\n",
      "  File \"C:\\ProgramData\\Anaconda3\\envs\\tf-gpu-26\\lib\\site-packages\\tensorflow\\python\\eager\\function.py\", line 3066, in _get_concrete_function_internal_garbage_collected\n",
      "    graph_function, _ = self._maybe_define_function(args, kwargs)\n",
      "  File \"C:\\ProgramData\\Anaconda3\\envs\\tf-gpu-26\\lib\\site-packages\\tensorflow\\python\\eager\\function.py\", line 3463, in _maybe_define_function\n",
      "    graph_function = self._create_graph_function(args, kwargs)\n",
      "  File \"C:\\ProgramData\\Anaconda3\\envs\\tf-gpu-26\\lib\\site-packages\\tensorflow\\python\\eager\\function.py\", line 3298, in _create_graph_function\n",
      "    func_graph_module.func_graph_from_py_func(\n",
      "  File \"C:\\ProgramData\\Anaconda3\\envs\\tf-gpu-26\\lib\\site-packages\\tensorflow\\python\\framework\\func_graph.py\", line 1007, in func_graph_from_py_func\n",
      "    func_outputs = python_func(*func_args, **func_kwargs)\n",
      "  File \"C:\\ProgramData\\Anaconda3\\envs\\tf-gpu-26\\lib\\site-packages\\tensorflow\\python\\eager\\def_function.py\", line 668, in wrapped_fn\n",
      "    out = weak_wrapped_fn().__wrapped__(*args, **kwds)\n",
      "  File \"C:\\ProgramData\\Anaconda3\\envs\\tf-gpu-26\\lib\\site-packages\\tensorflow\\python\\framework\\func_graph.py\", line 994, in wrapper\n",
      "    raise e.ag_error_metadata.to_exception(e)\n",
      "ValueError: in user code:\n",
      "\n",
      "    C:\\ProgramData\\Anaconda3\\envs\\tf-gpu-26\\lib\\site-packages\\keras\\engine\\training.py:853 train_function  *\n",
      "        return step_function(self, iterator)\n",
      "    C:\\ProgramData\\Anaconda3\\envs\\tf-gpu-26\\lib\\site-packages\\keras\\engine\\training.py:842 step_function  **\n",
      "        outputs = model.distribute_strategy.run(run_step, args=(data,))\n",
      "    C:\\ProgramData\\Anaconda3\\envs\\tf-gpu-26\\lib\\site-packages\\tensorflow\\python\\distribute\\distribute_lib.py:1286 run\n",
      "        return self._extended.call_for_each_replica(fn, args=args, kwargs=kwargs)\n",
      "    C:\\ProgramData\\Anaconda3\\envs\\tf-gpu-26\\lib\\site-packages\\tensorflow\\python\\distribute\\distribute_lib.py:2849 call_for_each_replica\n",
      "        return self._call_for_each_replica(fn, args, kwargs)\n",
      "    C:\\ProgramData\\Anaconda3\\envs\\tf-gpu-26\\lib\\site-packages\\tensorflow\\python\\distribute\\distribute_lib.py:3632 _call_for_each_replica\n",
      "        return fn(*args, **kwargs)\n",
      "    C:\\ProgramData\\Anaconda3\\envs\\tf-gpu-26\\lib\\site-packages\\keras\\engine\\training.py:835 run_step  **\n",
      "        outputs = model.train_step(data)\n",
      "    C:\\ProgramData\\Anaconda3\\envs\\tf-gpu-26\\lib\\site-packages\\keras\\engine\\training.py:788 train_step\n",
      "        loss = self.compiled_loss(\n",
      "    C:\\ProgramData\\Anaconda3\\envs\\tf-gpu-26\\lib\\site-packages\\keras\\engine\\compile_utils.py:201 __call__\n",
      "        loss_value = loss_obj(y_t, y_p, sample_weight=sw)\n",
      "    C:\\ProgramData\\Anaconda3\\envs\\tf-gpu-26\\lib\\site-packages\\keras\\losses.py:141 __call__\n",
      "        losses = call_fn(y_true, y_pred)\n",
      "    C:\\ProgramData\\Anaconda3\\envs\\tf-gpu-26\\lib\\site-packages\\keras\\losses.py:245 call  **\n",
      "        return ag_fn(y_true, y_pred, **self._fn_kwargs)\n",
      "    C:\\ProgramData\\Anaconda3\\envs\\tf-gpu-26\\lib\\site-packages\\tensorflow\\python\\util\\dispatch.py:206 wrapper\n",
      "        return target(*args, **kwargs)\n",
      "    C:\\ProgramData\\Anaconda3\\envs\\tf-gpu-26\\lib\\site-packages\\keras\\losses.py:1665 categorical_crossentropy\n",
      "        return backend.categorical_crossentropy(\n",
      "    C:\\ProgramData\\Anaconda3\\envs\\tf-gpu-26\\lib\\site-packages\\tensorflow\\python\\util\\dispatch.py:206 wrapper\n",
      "        return target(*args, **kwargs)\n",
      "    C:\\ProgramData\\Anaconda3\\envs\\tf-gpu-26\\lib\\site-packages\\keras\\backend.py:4839 categorical_crossentropy\n",
      "        target.shape.assert_is_compatible_with(output.shape)\n",
      "    C:\\ProgramData\\Anaconda3\\envs\\tf-gpu-26\\lib\\site-packages\\tensorflow\\python\\framework\\tensor_shape.py:1161 assert_is_compatible_with\n",
      "        raise ValueError(\"Shapes %s and %s are incompatible\" % (self, other))\n",
      "\n",
      "    ValueError: Shapes (5, 22) and (5, 3) are incompatible\n",
      "\n",
      "\n",
      "  warnings.warn(\"Estimator fit failed. The score on this train-test\"\n",
      "C:\\ProgramData\\Anaconda3\\envs\\tf-gpu-26\\lib\\site-packages\\sklearn\\model_selection\\_validation.py:615: FitFailedWarning: Estimator fit failed. The score on this train-test partition for these parameters will be set to nan. Details: \n",
      "Traceback (most recent call last):\n",
      "  File \"C:\\ProgramData\\Anaconda3\\envs\\tf-gpu-26\\lib\\site-packages\\sklearn\\model_selection\\_validation.py\", line 598, in _fit_and_score\n",
      "    estimator.fit(X_train, y_train, **fit_params)\n",
      "  File \"C:\\ProgramData\\Anaconda3\\envs\\tf-gpu-26\\lib\\site-packages\\keras\\wrappers\\scikit_learn.py\", line 219, in fit\n",
      "    return super(KerasClassifier, self).fit(x, y, **kwargs)\n",
      "  File \"C:\\ProgramData\\Anaconda3\\envs\\tf-gpu-26\\lib\\site-packages\\keras\\wrappers\\scikit_learn.py\", line 162, in fit\n",
      "    history = self.model.fit(x, y, **fit_args)\n",
      "  File \"C:\\ProgramData\\Anaconda3\\envs\\tf-gpu-26\\lib\\site-packages\\keras\\engine\\training.py\", line 1184, in fit\n",
      "    tmp_logs = self.train_function(iterator)\n",
      "  File \"C:\\ProgramData\\Anaconda3\\envs\\tf-gpu-26\\lib\\site-packages\\tensorflow\\python\\eager\\def_function.py\", line 885, in __call__\n",
      "    result = self._call(*args, **kwds)\n",
      "  File \"C:\\ProgramData\\Anaconda3\\envs\\tf-gpu-26\\lib\\site-packages\\tensorflow\\python\\eager\\def_function.py\", line 933, in _call\n",
      "    self._initialize(args, kwds, add_initializers_to=initializers)\n",
      "  File \"C:\\ProgramData\\Anaconda3\\envs\\tf-gpu-26\\lib\\site-packages\\tensorflow\\python\\eager\\def_function.py\", line 759, in _initialize\n",
      "    self._stateful_fn._get_concrete_function_internal_garbage_collected(  # pylint: disable=protected-access\n",
      "  File \"C:\\ProgramData\\Anaconda3\\envs\\tf-gpu-26\\lib\\site-packages\\tensorflow\\python\\eager\\function.py\", line 3066, in _get_concrete_function_internal_garbage_collected\n",
      "    graph_function, _ = self._maybe_define_function(args, kwargs)\n",
      "  File \"C:\\ProgramData\\Anaconda3\\envs\\tf-gpu-26\\lib\\site-packages\\tensorflow\\python\\eager\\function.py\", line 3463, in _maybe_define_function\n",
      "    graph_function = self._create_graph_function(args, kwargs)\n",
      "  File \"C:\\ProgramData\\Anaconda3\\envs\\tf-gpu-26\\lib\\site-packages\\tensorflow\\python\\eager\\function.py\", line 3298, in _create_graph_function\n",
      "    func_graph_module.func_graph_from_py_func(\n",
      "  File \"C:\\ProgramData\\Anaconda3\\envs\\tf-gpu-26\\lib\\site-packages\\tensorflow\\python\\framework\\func_graph.py\", line 1007, in func_graph_from_py_func\n",
      "    func_outputs = python_func(*func_args, **func_kwargs)\n",
      "  File \"C:\\ProgramData\\Anaconda3\\envs\\tf-gpu-26\\lib\\site-packages\\tensorflow\\python\\eager\\def_function.py\", line 668, in wrapped_fn\n",
      "    out = weak_wrapped_fn().__wrapped__(*args, **kwds)\n",
      "  File \"C:\\ProgramData\\Anaconda3\\envs\\tf-gpu-26\\lib\\site-packages\\tensorflow\\python\\framework\\func_graph.py\", line 994, in wrapper\n",
      "    raise e.ag_error_metadata.to_exception(e)\n",
      "ValueError: in user code:\n",
      "\n",
      "    C:\\ProgramData\\Anaconda3\\envs\\tf-gpu-26\\lib\\site-packages\\keras\\engine\\training.py:853 train_function  *\n",
      "        return step_function(self, iterator)\n",
      "    C:\\ProgramData\\Anaconda3\\envs\\tf-gpu-26\\lib\\site-packages\\keras\\engine\\training.py:842 step_function  **\n",
      "        outputs = model.distribute_strategy.run(run_step, args=(data,))\n",
      "    C:\\ProgramData\\Anaconda3\\envs\\tf-gpu-26\\lib\\site-packages\\tensorflow\\python\\distribute\\distribute_lib.py:1286 run\n",
      "        return self._extended.call_for_each_replica(fn, args=args, kwargs=kwargs)\n",
      "    C:\\ProgramData\\Anaconda3\\envs\\tf-gpu-26\\lib\\site-packages\\tensorflow\\python\\distribute\\distribute_lib.py:2849 call_for_each_replica\n",
      "        return self._call_for_each_replica(fn, args, kwargs)\n",
      "    C:\\ProgramData\\Anaconda3\\envs\\tf-gpu-26\\lib\\site-packages\\tensorflow\\python\\distribute\\distribute_lib.py:3632 _call_for_each_replica\n",
      "        return fn(*args, **kwargs)\n",
      "    C:\\ProgramData\\Anaconda3\\envs\\tf-gpu-26\\lib\\site-packages\\keras\\engine\\training.py:835 run_step  **\n",
      "        outputs = model.train_step(data)\n",
      "    C:\\ProgramData\\Anaconda3\\envs\\tf-gpu-26\\lib\\site-packages\\keras\\engine\\training.py:788 train_step\n",
      "        loss = self.compiled_loss(\n",
      "    C:\\ProgramData\\Anaconda3\\envs\\tf-gpu-26\\lib\\site-packages\\keras\\engine\\compile_utils.py:201 __call__\n",
      "        loss_value = loss_obj(y_t, y_p, sample_weight=sw)\n",
      "    C:\\ProgramData\\Anaconda3\\envs\\tf-gpu-26\\lib\\site-packages\\keras\\losses.py:141 __call__\n",
      "        losses = call_fn(y_true, y_pred)\n",
      "    C:\\ProgramData\\Anaconda3\\envs\\tf-gpu-26\\lib\\site-packages\\keras\\losses.py:245 call  **\n",
      "        return ag_fn(y_true, y_pred, **self._fn_kwargs)\n",
      "    C:\\ProgramData\\Anaconda3\\envs\\tf-gpu-26\\lib\\site-packages\\tensorflow\\python\\util\\dispatch.py:206 wrapper\n",
      "        return target(*args, **kwargs)\n",
      "    C:\\ProgramData\\Anaconda3\\envs\\tf-gpu-26\\lib\\site-packages\\keras\\losses.py:1665 categorical_crossentropy\n",
      "        return backend.categorical_crossentropy(\n",
      "    C:\\ProgramData\\Anaconda3\\envs\\tf-gpu-26\\lib\\site-packages\\tensorflow\\python\\util\\dispatch.py:206 wrapper\n",
      "        return target(*args, **kwargs)\n",
      "    C:\\ProgramData\\Anaconda3\\envs\\tf-gpu-26\\lib\\site-packages\\keras\\backend.py:4839 categorical_crossentropy\n",
      "        target.shape.assert_is_compatible_with(output.shape)\n",
      "    C:\\ProgramData\\Anaconda3\\envs\\tf-gpu-26\\lib\\site-packages\\tensorflow\\python\\framework\\tensor_shape.py:1161 assert_is_compatible_with\n",
      "        raise ValueError(\"Shapes %s and %s are incompatible\" % (self, other))\n",
      "\n",
      "    ValueError: Shapes (5, 22) and (5, 3) are incompatible\n",
      "\n",
      "\n",
      "  warnings.warn(\"Estimator fit failed. The score on this train-test\"\n"
     ]
    },
    {
     "name": "stdout",
     "output_type": "stream",
     "text": [
      "Epoch 1/200\n",
      "Epoch 1/200\n"
     ]
    },
    {
     "name": "stderr",
     "output_type": "stream",
     "text": [
      "C:\\ProgramData\\Anaconda3\\envs\\tf-gpu-26\\lib\\site-packages\\sklearn\\model_selection\\_validation.py:615: FitFailedWarning: Estimator fit failed. The score on this train-test partition for these parameters will be set to nan. Details: \n",
      "Traceback (most recent call last):\n",
      "  File \"C:\\ProgramData\\Anaconda3\\envs\\tf-gpu-26\\lib\\site-packages\\sklearn\\model_selection\\_validation.py\", line 598, in _fit_and_score\n",
      "    estimator.fit(X_train, y_train, **fit_params)\n",
      "  File \"C:\\ProgramData\\Anaconda3\\envs\\tf-gpu-26\\lib\\site-packages\\keras\\wrappers\\scikit_learn.py\", line 219, in fit\n",
      "    return super(KerasClassifier, self).fit(x, y, **kwargs)\n",
      "  File \"C:\\ProgramData\\Anaconda3\\envs\\tf-gpu-26\\lib\\site-packages\\keras\\wrappers\\scikit_learn.py\", line 162, in fit\n",
      "    history = self.model.fit(x, y, **fit_args)\n",
      "  File \"C:\\ProgramData\\Anaconda3\\envs\\tf-gpu-26\\lib\\site-packages\\keras\\engine\\training.py\", line 1184, in fit\n",
      "    tmp_logs = self.train_function(iterator)\n",
      "  File \"C:\\ProgramData\\Anaconda3\\envs\\tf-gpu-26\\lib\\site-packages\\tensorflow\\python\\eager\\def_function.py\", line 885, in __call__\n",
      "    result = self._call(*args, **kwds)\n",
      "  File \"C:\\ProgramData\\Anaconda3\\envs\\tf-gpu-26\\lib\\site-packages\\tensorflow\\python\\eager\\def_function.py\", line 933, in _call\n",
      "    self._initialize(args, kwds, add_initializers_to=initializers)\n",
      "  File \"C:\\ProgramData\\Anaconda3\\envs\\tf-gpu-26\\lib\\site-packages\\tensorflow\\python\\eager\\def_function.py\", line 759, in _initialize\n",
      "    self._stateful_fn._get_concrete_function_internal_garbage_collected(  # pylint: disable=protected-access\n",
      "  File \"C:\\ProgramData\\Anaconda3\\envs\\tf-gpu-26\\lib\\site-packages\\tensorflow\\python\\eager\\function.py\", line 3066, in _get_concrete_function_internal_garbage_collected\n",
      "    graph_function, _ = self._maybe_define_function(args, kwargs)\n",
      "  File \"C:\\ProgramData\\Anaconda3\\envs\\tf-gpu-26\\lib\\site-packages\\tensorflow\\python\\eager\\function.py\", line 3463, in _maybe_define_function\n",
      "    graph_function = self._create_graph_function(args, kwargs)\n",
      "  File \"C:\\ProgramData\\Anaconda3\\envs\\tf-gpu-26\\lib\\site-packages\\tensorflow\\python\\eager\\function.py\", line 3298, in _create_graph_function\n",
      "    func_graph_module.func_graph_from_py_func(\n",
      "  File \"C:\\ProgramData\\Anaconda3\\envs\\tf-gpu-26\\lib\\site-packages\\tensorflow\\python\\framework\\func_graph.py\", line 1007, in func_graph_from_py_func\n",
      "    func_outputs = python_func(*func_args, **func_kwargs)\n",
      "  File \"C:\\ProgramData\\Anaconda3\\envs\\tf-gpu-26\\lib\\site-packages\\tensorflow\\python\\eager\\def_function.py\", line 668, in wrapped_fn\n",
      "    out = weak_wrapped_fn().__wrapped__(*args, **kwds)\n",
      "  File \"C:\\ProgramData\\Anaconda3\\envs\\tf-gpu-26\\lib\\site-packages\\tensorflow\\python\\framework\\func_graph.py\", line 994, in wrapper\n",
      "    raise e.ag_error_metadata.to_exception(e)\n",
      "ValueError: in user code:\n",
      "\n",
      "    C:\\ProgramData\\Anaconda3\\envs\\tf-gpu-26\\lib\\site-packages\\keras\\engine\\training.py:853 train_function  *\n",
      "        return step_function(self, iterator)\n",
      "    C:\\ProgramData\\Anaconda3\\envs\\tf-gpu-26\\lib\\site-packages\\keras\\engine\\training.py:842 step_function  **\n",
      "        outputs = model.distribute_strategy.run(run_step, args=(data,))\n",
      "    C:\\ProgramData\\Anaconda3\\envs\\tf-gpu-26\\lib\\site-packages\\tensorflow\\python\\distribute\\distribute_lib.py:1286 run\n",
      "        return self._extended.call_for_each_replica(fn, args=args, kwargs=kwargs)\n",
      "    C:\\ProgramData\\Anaconda3\\envs\\tf-gpu-26\\lib\\site-packages\\tensorflow\\python\\distribute\\distribute_lib.py:2849 call_for_each_replica\n",
      "        return self._call_for_each_replica(fn, args, kwargs)\n",
      "    C:\\ProgramData\\Anaconda3\\envs\\tf-gpu-26\\lib\\site-packages\\tensorflow\\python\\distribute\\distribute_lib.py:3632 _call_for_each_replica\n",
      "        return fn(*args, **kwargs)\n",
      "    C:\\ProgramData\\Anaconda3\\envs\\tf-gpu-26\\lib\\site-packages\\keras\\engine\\training.py:835 run_step  **\n",
      "        outputs = model.train_step(data)\n",
      "    C:\\ProgramData\\Anaconda3\\envs\\tf-gpu-26\\lib\\site-packages\\keras\\engine\\training.py:788 train_step\n",
      "        loss = self.compiled_loss(\n",
      "    C:\\ProgramData\\Anaconda3\\envs\\tf-gpu-26\\lib\\site-packages\\keras\\engine\\compile_utils.py:201 __call__\n",
      "        loss_value = loss_obj(y_t, y_p, sample_weight=sw)\n",
      "    C:\\ProgramData\\Anaconda3\\envs\\tf-gpu-26\\lib\\site-packages\\keras\\losses.py:141 __call__\n",
      "        losses = call_fn(y_true, y_pred)\n",
      "    C:\\ProgramData\\Anaconda3\\envs\\tf-gpu-26\\lib\\site-packages\\keras\\losses.py:245 call  **\n",
      "        return ag_fn(y_true, y_pred, **self._fn_kwargs)\n",
      "    C:\\ProgramData\\Anaconda3\\envs\\tf-gpu-26\\lib\\site-packages\\tensorflow\\python\\util\\dispatch.py:206 wrapper\n",
      "        return target(*args, **kwargs)\n",
      "    C:\\ProgramData\\Anaconda3\\envs\\tf-gpu-26\\lib\\site-packages\\keras\\losses.py:1665 categorical_crossentropy\n",
      "        return backend.categorical_crossentropy(\n",
      "    C:\\ProgramData\\Anaconda3\\envs\\tf-gpu-26\\lib\\site-packages\\tensorflow\\python\\util\\dispatch.py:206 wrapper\n",
      "        return target(*args, **kwargs)\n",
      "    C:\\ProgramData\\Anaconda3\\envs\\tf-gpu-26\\lib\\site-packages\\keras\\backend.py:4839 categorical_crossentropy\n",
      "        target.shape.assert_is_compatible_with(output.shape)\n",
      "    C:\\ProgramData\\Anaconda3\\envs\\tf-gpu-26\\lib\\site-packages\\tensorflow\\python\\framework\\tensor_shape.py:1161 assert_is_compatible_with\n",
      "        raise ValueError(\"Shapes %s and %s are incompatible\" % (self, other))\n",
      "\n",
      "    ValueError: Shapes (5, 22) and (5, 3) are incompatible\n",
      "\n",
      "\n",
      "  warnings.warn(\"Estimator fit failed. The score on this train-test\"\n",
      "C:\\ProgramData\\Anaconda3\\envs\\tf-gpu-26\\lib\\site-packages\\sklearn\\model_selection\\_validation.py:615: FitFailedWarning: Estimator fit failed. The score on this train-test partition for these parameters will be set to nan. Details: \n",
      "Traceback (most recent call last):\n",
      "  File \"C:\\ProgramData\\Anaconda3\\envs\\tf-gpu-26\\lib\\site-packages\\sklearn\\model_selection\\_validation.py\", line 598, in _fit_and_score\n",
      "    estimator.fit(X_train, y_train, **fit_params)\n",
      "  File \"C:\\ProgramData\\Anaconda3\\envs\\tf-gpu-26\\lib\\site-packages\\keras\\wrappers\\scikit_learn.py\", line 219, in fit\n",
      "    return super(KerasClassifier, self).fit(x, y, **kwargs)\n",
      "  File \"C:\\ProgramData\\Anaconda3\\envs\\tf-gpu-26\\lib\\site-packages\\keras\\wrappers\\scikit_learn.py\", line 162, in fit\n",
      "    history = self.model.fit(x, y, **fit_args)\n",
      "  File \"C:\\ProgramData\\Anaconda3\\envs\\tf-gpu-26\\lib\\site-packages\\keras\\engine\\training.py\", line 1184, in fit\n",
      "    tmp_logs = self.train_function(iterator)\n",
      "  File \"C:\\ProgramData\\Anaconda3\\envs\\tf-gpu-26\\lib\\site-packages\\tensorflow\\python\\eager\\def_function.py\", line 885, in __call__\n",
      "    result = self._call(*args, **kwds)\n",
      "  File \"C:\\ProgramData\\Anaconda3\\envs\\tf-gpu-26\\lib\\site-packages\\tensorflow\\python\\eager\\def_function.py\", line 933, in _call\n",
      "    self._initialize(args, kwds, add_initializers_to=initializers)\n",
      "  File \"C:\\ProgramData\\Anaconda3\\envs\\tf-gpu-26\\lib\\site-packages\\tensorflow\\python\\eager\\def_function.py\", line 759, in _initialize\n",
      "    self._stateful_fn._get_concrete_function_internal_garbage_collected(  # pylint: disable=protected-access\n",
      "  File \"C:\\ProgramData\\Anaconda3\\envs\\tf-gpu-26\\lib\\site-packages\\tensorflow\\python\\eager\\function.py\", line 3066, in _get_concrete_function_internal_garbage_collected\n",
      "    graph_function, _ = self._maybe_define_function(args, kwargs)\n",
      "  File \"C:\\ProgramData\\Anaconda3\\envs\\tf-gpu-26\\lib\\site-packages\\tensorflow\\python\\eager\\function.py\", line 3463, in _maybe_define_function\n",
      "    graph_function = self._create_graph_function(args, kwargs)\n",
      "  File \"C:\\ProgramData\\Anaconda3\\envs\\tf-gpu-26\\lib\\site-packages\\tensorflow\\python\\eager\\function.py\", line 3298, in _create_graph_function\n",
      "    func_graph_module.func_graph_from_py_func(\n",
      "  File \"C:\\ProgramData\\Anaconda3\\envs\\tf-gpu-26\\lib\\site-packages\\tensorflow\\python\\framework\\func_graph.py\", line 1007, in func_graph_from_py_func\n",
      "    func_outputs = python_func(*func_args, **func_kwargs)\n",
      "  File \"C:\\ProgramData\\Anaconda3\\envs\\tf-gpu-26\\lib\\site-packages\\tensorflow\\python\\eager\\def_function.py\", line 668, in wrapped_fn\n",
      "    out = weak_wrapped_fn().__wrapped__(*args, **kwds)\n",
      "  File \"C:\\ProgramData\\Anaconda3\\envs\\tf-gpu-26\\lib\\site-packages\\tensorflow\\python\\framework\\func_graph.py\", line 994, in wrapper\n",
      "    raise e.ag_error_metadata.to_exception(e)\n",
      "ValueError: in user code:\n",
      "\n",
      "    C:\\ProgramData\\Anaconda3\\envs\\tf-gpu-26\\lib\\site-packages\\keras\\engine\\training.py:853 train_function  *\n",
      "        return step_function(self, iterator)\n",
      "    C:\\ProgramData\\Anaconda3\\envs\\tf-gpu-26\\lib\\site-packages\\keras\\engine\\training.py:842 step_function  **\n",
      "        outputs = model.distribute_strategy.run(run_step, args=(data,))\n",
      "    C:\\ProgramData\\Anaconda3\\envs\\tf-gpu-26\\lib\\site-packages\\tensorflow\\python\\distribute\\distribute_lib.py:1286 run\n",
      "        return self._extended.call_for_each_replica(fn, args=args, kwargs=kwargs)\n",
      "    C:\\ProgramData\\Anaconda3\\envs\\tf-gpu-26\\lib\\site-packages\\tensorflow\\python\\distribute\\distribute_lib.py:2849 call_for_each_replica\n",
      "        return self._call_for_each_replica(fn, args, kwargs)\n",
      "    C:\\ProgramData\\Anaconda3\\envs\\tf-gpu-26\\lib\\site-packages\\tensorflow\\python\\distribute\\distribute_lib.py:3632 _call_for_each_replica\n",
      "        return fn(*args, **kwargs)\n",
      "    C:\\ProgramData\\Anaconda3\\envs\\tf-gpu-26\\lib\\site-packages\\keras\\engine\\training.py:835 run_step  **\n",
      "        outputs = model.train_step(data)\n",
      "    C:\\ProgramData\\Anaconda3\\envs\\tf-gpu-26\\lib\\site-packages\\keras\\engine\\training.py:788 train_step\n",
      "        loss = self.compiled_loss(\n",
      "    C:\\ProgramData\\Anaconda3\\envs\\tf-gpu-26\\lib\\site-packages\\keras\\engine\\compile_utils.py:201 __call__\n",
      "        loss_value = loss_obj(y_t, y_p, sample_weight=sw)\n",
      "    C:\\ProgramData\\Anaconda3\\envs\\tf-gpu-26\\lib\\site-packages\\keras\\losses.py:141 __call__\n",
      "        losses = call_fn(y_true, y_pred)\n",
      "    C:\\ProgramData\\Anaconda3\\envs\\tf-gpu-26\\lib\\site-packages\\keras\\losses.py:245 call  **\n",
      "        return ag_fn(y_true, y_pred, **self._fn_kwargs)\n",
      "    C:\\ProgramData\\Anaconda3\\envs\\tf-gpu-26\\lib\\site-packages\\tensorflow\\python\\util\\dispatch.py:206 wrapper\n",
      "        return target(*args, **kwargs)\n",
      "    C:\\ProgramData\\Anaconda3\\envs\\tf-gpu-26\\lib\\site-packages\\keras\\losses.py:1665 categorical_crossentropy\n",
      "        return backend.categorical_crossentropy(\n",
      "    C:\\ProgramData\\Anaconda3\\envs\\tf-gpu-26\\lib\\site-packages\\tensorflow\\python\\util\\dispatch.py:206 wrapper\n",
      "        return target(*args, **kwargs)\n",
      "    C:\\ProgramData\\Anaconda3\\envs\\tf-gpu-26\\lib\\site-packages\\keras\\backend.py:4839 categorical_crossentropy\n",
      "        target.shape.assert_is_compatible_with(output.shape)\n",
      "    C:\\ProgramData\\Anaconda3\\envs\\tf-gpu-26\\lib\\site-packages\\tensorflow\\python\\framework\\tensor_shape.py:1161 assert_is_compatible_with\n",
      "        raise ValueError(\"Shapes %s and %s are incompatible\" % (self, other))\n",
      "\n",
      "    ValueError: Shapes (5, 22) and (5, 3) are incompatible\n",
      "\n",
      "\n",
      "  warnings.warn(\"Estimator fit failed. The score on this train-test\"\n"
     ]
    },
    {
     "name": "stdout",
     "output_type": "stream",
     "text": [
      "Epoch 1/200\n"
     ]
    },
    {
     "name": "stderr",
     "output_type": "stream",
     "text": [
      "C:\\ProgramData\\Anaconda3\\envs\\tf-gpu-26\\lib\\site-packages\\sklearn\\model_selection\\_validation.py:615: FitFailedWarning: Estimator fit failed. The score on this train-test partition for these parameters will be set to nan. Details: \n",
      "Traceback (most recent call last):\n",
      "  File \"C:\\ProgramData\\Anaconda3\\envs\\tf-gpu-26\\lib\\site-packages\\sklearn\\model_selection\\_validation.py\", line 598, in _fit_and_score\n",
      "    estimator.fit(X_train, y_train, **fit_params)\n",
      "  File \"C:\\ProgramData\\Anaconda3\\envs\\tf-gpu-26\\lib\\site-packages\\keras\\wrappers\\scikit_learn.py\", line 219, in fit\n",
      "    return super(KerasClassifier, self).fit(x, y, **kwargs)\n",
      "  File \"C:\\ProgramData\\Anaconda3\\envs\\tf-gpu-26\\lib\\site-packages\\keras\\wrappers\\scikit_learn.py\", line 162, in fit\n",
      "    history = self.model.fit(x, y, **fit_args)\n",
      "  File \"C:\\ProgramData\\Anaconda3\\envs\\tf-gpu-26\\lib\\site-packages\\keras\\engine\\training.py\", line 1184, in fit\n",
      "    tmp_logs = self.train_function(iterator)\n",
      "  File \"C:\\ProgramData\\Anaconda3\\envs\\tf-gpu-26\\lib\\site-packages\\tensorflow\\python\\eager\\def_function.py\", line 885, in __call__\n",
      "    result = self._call(*args, **kwds)\n",
      "  File \"C:\\ProgramData\\Anaconda3\\envs\\tf-gpu-26\\lib\\site-packages\\tensorflow\\python\\eager\\def_function.py\", line 933, in _call\n",
      "    self._initialize(args, kwds, add_initializers_to=initializers)\n",
      "  File \"C:\\ProgramData\\Anaconda3\\envs\\tf-gpu-26\\lib\\site-packages\\tensorflow\\python\\eager\\def_function.py\", line 759, in _initialize\n",
      "    self._stateful_fn._get_concrete_function_internal_garbage_collected(  # pylint: disable=protected-access\n",
      "  File \"C:\\ProgramData\\Anaconda3\\envs\\tf-gpu-26\\lib\\site-packages\\tensorflow\\python\\eager\\function.py\", line 3066, in _get_concrete_function_internal_garbage_collected\n",
      "    graph_function, _ = self._maybe_define_function(args, kwargs)\n",
      "  File \"C:\\ProgramData\\Anaconda3\\envs\\tf-gpu-26\\lib\\site-packages\\tensorflow\\python\\eager\\function.py\", line 3463, in _maybe_define_function\n",
      "    graph_function = self._create_graph_function(args, kwargs)\n",
      "  File \"C:\\ProgramData\\Anaconda3\\envs\\tf-gpu-26\\lib\\site-packages\\tensorflow\\python\\eager\\function.py\", line 3298, in _create_graph_function\n",
      "    func_graph_module.func_graph_from_py_func(\n",
      "  File \"C:\\ProgramData\\Anaconda3\\envs\\tf-gpu-26\\lib\\site-packages\\tensorflow\\python\\framework\\func_graph.py\", line 1007, in func_graph_from_py_func\n",
      "    func_outputs = python_func(*func_args, **func_kwargs)\n",
      "  File \"C:\\ProgramData\\Anaconda3\\envs\\tf-gpu-26\\lib\\site-packages\\tensorflow\\python\\eager\\def_function.py\", line 668, in wrapped_fn\n",
      "    out = weak_wrapped_fn().__wrapped__(*args, **kwds)\n",
      "  File \"C:\\ProgramData\\Anaconda3\\envs\\tf-gpu-26\\lib\\site-packages\\tensorflow\\python\\framework\\func_graph.py\", line 994, in wrapper\n",
      "    raise e.ag_error_metadata.to_exception(e)\n",
      "ValueError: in user code:\n",
      "\n",
      "    C:\\ProgramData\\Anaconda3\\envs\\tf-gpu-26\\lib\\site-packages\\keras\\engine\\training.py:853 train_function  *\n",
      "        return step_function(self, iterator)\n",
      "    C:\\ProgramData\\Anaconda3\\envs\\tf-gpu-26\\lib\\site-packages\\keras\\engine\\training.py:842 step_function  **\n",
      "        outputs = model.distribute_strategy.run(run_step, args=(data,))\n",
      "    C:\\ProgramData\\Anaconda3\\envs\\tf-gpu-26\\lib\\site-packages\\tensorflow\\python\\distribute\\distribute_lib.py:1286 run\n",
      "        return self._extended.call_for_each_replica(fn, args=args, kwargs=kwargs)\n",
      "    C:\\ProgramData\\Anaconda3\\envs\\tf-gpu-26\\lib\\site-packages\\tensorflow\\python\\distribute\\distribute_lib.py:2849 call_for_each_replica\n",
      "        return self._call_for_each_replica(fn, args, kwargs)\n",
      "    C:\\ProgramData\\Anaconda3\\envs\\tf-gpu-26\\lib\\site-packages\\tensorflow\\python\\distribute\\distribute_lib.py:3632 _call_for_each_replica\n",
      "        return fn(*args, **kwargs)\n",
      "    C:\\ProgramData\\Anaconda3\\envs\\tf-gpu-26\\lib\\site-packages\\keras\\engine\\training.py:835 run_step  **\n",
      "        outputs = model.train_step(data)\n",
      "    C:\\ProgramData\\Anaconda3\\envs\\tf-gpu-26\\lib\\site-packages\\keras\\engine\\training.py:788 train_step\n",
      "        loss = self.compiled_loss(\n",
      "    C:\\ProgramData\\Anaconda3\\envs\\tf-gpu-26\\lib\\site-packages\\keras\\engine\\compile_utils.py:201 __call__\n",
      "        loss_value = loss_obj(y_t, y_p, sample_weight=sw)\n",
      "    C:\\ProgramData\\Anaconda3\\envs\\tf-gpu-26\\lib\\site-packages\\keras\\losses.py:141 __call__\n",
      "        losses = call_fn(y_true, y_pred)\n",
      "    C:\\ProgramData\\Anaconda3\\envs\\tf-gpu-26\\lib\\site-packages\\keras\\losses.py:245 call  **\n",
      "        return ag_fn(y_true, y_pred, **self._fn_kwargs)\n",
      "    C:\\ProgramData\\Anaconda3\\envs\\tf-gpu-26\\lib\\site-packages\\tensorflow\\python\\util\\dispatch.py:206 wrapper\n",
      "        return target(*args, **kwargs)\n",
      "    C:\\ProgramData\\Anaconda3\\envs\\tf-gpu-26\\lib\\site-packages\\keras\\losses.py:1665 categorical_crossentropy\n",
      "        return backend.categorical_crossentropy(\n",
      "    C:\\ProgramData\\Anaconda3\\envs\\tf-gpu-26\\lib\\site-packages\\tensorflow\\python\\util\\dispatch.py:206 wrapper\n",
      "        return target(*args, **kwargs)\n",
      "    C:\\ProgramData\\Anaconda3\\envs\\tf-gpu-26\\lib\\site-packages\\keras\\backend.py:4839 categorical_crossentropy\n",
      "        target.shape.assert_is_compatible_with(output.shape)\n",
      "    C:\\ProgramData\\Anaconda3\\envs\\tf-gpu-26\\lib\\site-packages\\tensorflow\\python\\framework\\tensor_shape.py:1161 assert_is_compatible_with\n",
      "        raise ValueError(\"Shapes %s and %s are incompatible\" % (self, other))\n",
      "\n",
      "    ValueError: Shapes (5, 22) and (5, 3) are incompatible\n",
      "\n",
      "\n",
      "  warnings.warn(\"Estimator fit failed. The score on this train-test\"\n"
     ]
    }
   ],
   "source": [
    "results = cross_val_score(estimator, X, dummy_y, cv=kfold)"
   ]
  },
  {
   "cell_type": "code",
   "execution_count": 20,
   "id": "40990960",
   "metadata": {},
   "outputs": [
    {
     "name": "stdout",
     "output_type": "stream",
     "text": [
      "Baseline: nan% (nan%)\n"
     ]
    }
   ],
   "source": [
    "print(\"Baseline: %.2f%% (%.2f%%)\" % (results.mean()*100, results.std()*100))\n"
   ]
  },
  {
   "cell_type": "code",
   "execution_count": null,
   "id": "aac4982a",
   "metadata": {},
   "outputs": [],
   "source": []
  },
  {
   "cell_type": "code",
   "execution_count": 21,
   "id": "c764d1c8",
   "metadata": {},
   "outputs": [
    {
     "name": "stderr",
     "output_type": "stream",
     "text": [
      "C:\\ProgramData\\Anaconda3\\envs\\tf-gpu-26\\lib\\site-packages\\sklearn\\model_selection\\_validation.py:615: FitFailedWarning: Estimator fit failed. The score on this train-test partition for these parameters will be set to nan. Details: \n",
      "Traceback (most recent call last):\n",
      "  File \"C:\\ProgramData\\Anaconda3\\envs\\tf-gpu-26\\lib\\site-packages\\sklearn\\model_selection\\_validation.py\", line 598, in _fit_and_score\n",
      "    estimator.fit(X_train, y_train, **fit_params)\n",
      "  File \"C:\\ProgramData\\Anaconda3\\envs\\tf-gpu-26\\lib\\site-packages\\keras\\wrappers\\scikit_learn.py\", line 219, in fit\n",
      "    return super(KerasClassifier, self).fit(x, y, **kwargs)\n",
      "  File \"C:\\ProgramData\\Anaconda3\\envs\\tf-gpu-26\\lib\\site-packages\\keras\\wrappers\\scikit_learn.py\", line 162, in fit\n",
      "    history = self.model.fit(x, y, **fit_args)\n",
      "  File \"C:\\ProgramData\\Anaconda3\\envs\\tf-gpu-26\\lib\\site-packages\\keras\\engine\\training.py\", line 1184, in fit\n",
      "    tmp_logs = self.train_function(iterator)\n",
      "  File \"C:\\ProgramData\\Anaconda3\\envs\\tf-gpu-26\\lib\\site-packages\\tensorflow\\python\\eager\\def_function.py\", line 885, in __call__\n",
      "    result = self._call(*args, **kwds)\n",
      "  File \"C:\\ProgramData\\Anaconda3\\envs\\tf-gpu-26\\lib\\site-packages\\tensorflow\\python\\eager\\def_function.py\", line 933, in _call\n",
      "    self._initialize(args, kwds, add_initializers_to=initializers)\n",
      "  File \"C:\\ProgramData\\Anaconda3\\envs\\tf-gpu-26\\lib\\site-packages\\tensorflow\\python\\eager\\def_function.py\", line 759, in _initialize\n",
      "    self._stateful_fn._get_concrete_function_internal_garbage_collected(  # pylint: disable=protected-access\n",
      "  File \"C:\\ProgramData\\Anaconda3\\envs\\tf-gpu-26\\lib\\site-packages\\tensorflow\\python\\eager\\function.py\", line 3066, in _get_concrete_function_internal_garbage_collected\n",
      "    graph_function, _ = self._maybe_define_function(args, kwargs)\n",
      "  File \"C:\\ProgramData\\Anaconda3\\envs\\tf-gpu-26\\lib\\site-packages\\tensorflow\\python\\eager\\function.py\", line 3463, in _maybe_define_function\n",
      "    graph_function = self._create_graph_function(args, kwargs)\n",
      "  File \"C:\\ProgramData\\Anaconda3\\envs\\tf-gpu-26\\lib\\site-packages\\tensorflow\\python\\eager\\function.py\", line 3298, in _create_graph_function\n",
      "    func_graph_module.func_graph_from_py_func(\n",
      "  File \"C:\\ProgramData\\Anaconda3\\envs\\tf-gpu-26\\lib\\site-packages\\tensorflow\\python\\framework\\func_graph.py\", line 1007, in func_graph_from_py_func\n",
      "    func_outputs = python_func(*func_args, **func_kwargs)\n",
      "  File \"C:\\ProgramData\\Anaconda3\\envs\\tf-gpu-26\\lib\\site-packages\\tensorflow\\python\\eager\\def_function.py\", line 668, in wrapped_fn\n",
      "    out = weak_wrapped_fn().__wrapped__(*args, **kwds)\n",
      "  File \"C:\\ProgramData\\Anaconda3\\envs\\tf-gpu-26\\lib\\site-packages\\tensorflow\\python\\framework\\func_graph.py\", line 994, in wrapper\n",
      "    raise e.ag_error_metadata.to_exception(e)\n",
      "ValueError: in user code:\n",
      "\n",
      "    C:\\ProgramData\\Anaconda3\\envs\\tf-gpu-26\\lib\\site-packages\\keras\\engine\\training.py:853 train_function  *\n",
      "        return step_function(self, iterator)\n",
      "    C:\\ProgramData\\Anaconda3\\envs\\tf-gpu-26\\lib\\site-packages\\keras\\engine\\training.py:842 step_function  **\n",
      "        outputs = model.distribute_strategy.run(run_step, args=(data,))\n",
      "    C:\\ProgramData\\Anaconda3\\envs\\tf-gpu-26\\lib\\site-packages\\tensorflow\\python\\distribute\\distribute_lib.py:1286 run\n",
      "        return self._extended.call_for_each_replica(fn, args=args, kwargs=kwargs)\n",
      "    C:\\ProgramData\\Anaconda3\\envs\\tf-gpu-26\\lib\\site-packages\\tensorflow\\python\\distribute\\distribute_lib.py:2849 call_for_each_replica\n",
      "        return self._call_for_each_replica(fn, args, kwargs)\n",
      "    C:\\ProgramData\\Anaconda3\\envs\\tf-gpu-26\\lib\\site-packages\\tensorflow\\python\\distribute\\distribute_lib.py:3632 _call_for_each_replica\n",
      "        return fn(*args, **kwargs)\n",
      "    C:\\ProgramData\\Anaconda3\\envs\\tf-gpu-26\\lib\\site-packages\\keras\\engine\\training.py:835 run_step  **\n",
      "        outputs = model.train_step(data)\n",
      "    C:\\ProgramData\\Anaconda3\\envs\\tf-gpu-26\\lib\\site-packages\\keras\\engine\\training.py:788 train_step\n",
      "        loss = self.compiled_loss(\n",
      "    C:\\ProgramData\\Anaconda3\\envs\\tf-gpu-26\\lib\\site-packages\\keras\\engine\\compile_utils.py:201 __call__\n",
      "        loss_value = loss_obj(y_t, y_p, sample_weight=sw)\n",
      "    C:\\ProgramData\\Anaconda3\\envs\\tf-gpu-26\\lib\\site-packages\\keras\\losses.py:141 __call__\n",
      "        losses = call_fn(y_true, y_pred)\n",
      "    C:\\ProgramData\\Anaconda3\\envs\\tf-gpu-26\\lib\\site-packages\\keras\\losses.py:245 call  **\n",
      "        return ag_fn(y_true, y_pred, **self._fn_kwargs)\n",
      "    C:\\ProgramData\\Anaconda3\\envs\\tf-gpu-26\\lib\\site-packages\\tensorflow\\python\\util\\dispatch.py:206 wrapper\n",
      "        return target(*args, **kwargs)\n",
      "    C:\\ProgramData\\Anaconda3\\envs\\tf-gpu-26\\lib\\site-packages\\keras\\losses.py:1665 categorical_crossentropy\n",
      "        return backend.categorical_crossentropy(\n",
      "    C:\\ProgramData\\Anaconda3\\envs\\tf-gpu-26\\lib\\site-packages\\tensorflow\\python\\util\\dispatch.py:206 wrapper\n",
      "        return target(*args, **kwargs)\n",
      "    C:\\ProgramData\\Anaconda3\\envs\\tf-gpu-26\\lib\\site-packages\\keras\\backend.py:4839 categorical_crossentropy\n",
      "        target.shape.assert_is_compatible_with(output.shape)\n",
      "    C:\\ProgramData\\Anaconda3\\envs\\tf-gpu-26\\lib\\site-packages\\tensorflow\\python\\framework\\tensor_shape.py:1161 assert_is_compatible_with\n",
      "        raise ValueError(\"Shapes %s and %s are incompatible\" % (self, other))\n",
      "\n",
      "    ValueError: Shapes (5, 22) and (5, 3) are incompatible\n",
      "\n",
      "\n",
      "  warnings.warn(\"Estimator fit failed. The score on this train-test\"\n",
      "C:\\ProgramData\\Anaconda3\\envs\\tf-gpu-26\\lib\\site-packages\\sklearn\\model_selection\\_validation.py:615: FitFailedWarning: Estimator fit failed. The score on this train-test partition for these parameters will be set to nan. Details: \n",
      "Traceback (most recent call last):\n",
      "  File \"C:\\ProgramData\\Anaconda3\\envs\\tf-gpu-26\\lib\\site-packages\\sklearn\\model_selection\\_validation.py\", line 598, in _fit_and_score\n",
      "    estimator.fit(X_train, y_train, **fit_params)\n",
      "  File \"C:\\ProgramData\\Anaconda3\\envs\\tf-gpu-26\\lib\\site-packages\\keras\\wrappers\\scikit_learn.py\", line 219, in fit\n",
      "    return super(KerasClassifier, self).fit(x, y, **kwargs)\n",
      "  File \"C:\\ProgramData\\Anaconda3\\envs\\tf-gpu-26\\lib\\site-packages\\keras\\wrappers\\scikit_learn.py\", line 162, in fit\n",
      "    history = self.model.fit(x, y, **fit_args)\n",
      "  File \"C:\\ProgramData\\Anaconda3\\envs\\tf-gpu-26\\lib\\site-packages\\keras\\engine\\training.py\", line 1184, in fit\n",
      "    tmp_logs = self.train_function(iterator)\n",
      "  File \"C:\\ProgramData\\Anaconda3\\envs\\tf-gpu-26\\lib\\site-packages\\tensorflow\\python\\eager\\def_function.py\", line 885, in __call__\n",
      "    result = self._call(*args, **kwds)\n",
      "  File \"C:\\ProgramData\\Anaconda3\\envs\\tf-gpu-26\\lib\\site-packages\\tensorflow\\python\\eager\\def_function.py\", line 933, in _call\n",
      "    self._initialize(args, kwds, add_initializers_to=initializers)\n",
      "  File \"C:\\ProgramData\\Anaconda3\\envs\\tf-gpu-26\\lib\\site-packages\\tensorflow\\python\\eager\\def_function.py\", line 759, in _initialize\n",
      "    self._stateful_fn._get_concrete_function_internal_garbage_collected(  # pylint: disable=protected-access\n",
      "  File \"C:\\ProgramData\\Anaconda3\\envs\\tf-gpu-26\\lib\\site-packages\\tensorflow\\python\\eager\\function.py\", line 3066, in _get_concrete_function_internal_garbage_collected\n",
      "    graph_function, _ = self._maybe_define_function(args, kwargs)\n",
      "  File \"C:\\ProgramData\\Anaconda3\\envs\\tf-gpu-26\\lib\\site-packages\\tensorflow\\python\\eager\\function.py\", line 3463, in _maybe_define_function\n",
      "    graph_function = self._create_graph_function(args, kwargs)\n",
      "  File \"C:\\ProgramData\\Anaconda3\\envs\\tf-gpu-26\\lib\\site-packages\\tensorflow\\python\\eager\\function.py\", line 3298, in _create_graph_function\n",
      "    func_graph_module.func_graph_from_py_func(\n",
      "  File \"C:\\ProgramData\\Anaconda3\\envs\\tf-gpu-26\\lib\\site-packages\\tensorflow\\python\\framework\\func_graph.py\", line 1007, in func_graph_from_py_func\n",
      "    func_outputs = python_func(*func_args, **func_kwargs)\n",
      "  File \"C:\\ProgramData\\Anaconda3\\envs\\tf-gpu-26\\lib\\site-packages\\tensorflow\\python\\eager\\def_function.py\", line 668, in wrapped_fn\n",
      "    out = weak_wrapped_fn().__wrapped__(*args, **kwds)\n",
      "  File \"C:\\ProgramData\\Anaconda3\\envs\\tf-gpu-26\\lib\\site-packages\\tensorflow\\python\\framework\\func_graph.py\", line 994, in wrapper\n",
      "    raise e.ag_error_metadata.to_exception(e)\n",
      "ValueError: in user code:\n",
      "\n",
      "    C:\\ProgramData\\Anaconda3\\envs\\tf-gpu-26\\lib\\site-packages\\keras\\engine\\training.py:853 train_function  *\n",
      "        return step_function(self, iterator)\n",
      "    C:\\ProgramData\\Anaconda3\\envs\\tf-gpu-26\\lib\\site-packages\\keras\\engine\\training.py:842 step_function  **\n",
      "        outputs = model.distribute_strategy.run(run_step, args=(data,))\n",
      "    C:\\ProgramData\\Anaconda3\\envs\\tf-gpu-26\\lib\\site-packages\\tensorflow\\python\\distribute\\distribute_lib.py:1286 run\n",
      "        return self._extended.call_for_each_replica(fn, args=args, kwargs=kwargs)\n",
      "    C:\\ProgramData\\Anaconda3\\envs\\tf-gpu-26\\lib\\site-packages\\tensorflow\\python\\distribute\\distribute_lib.py:2849 call_for_each_replica\n",
      "        return self._call_for_each_replica(fn, args, kwargs)\n",
      "    C:\\ProgramData\\Anaconda3\\envs\\tf-gpu-26\\lib\\site-packages\\tensorflow\\python\\distribute\\distribute_lib.py:3632 _call_for_each_replica\n",
      "        return fn(*args, **kwargs)\n",
      "    C:\\ProgramData\\Anaconda3\\envs\\tf-gpu-26\\lib\\site-packages\\keras\\engine\\training.py:835 run_step  **\n",
      "        outputs = model.train_step(data)\n",
      "    C:\\ProgramData\\Anaconda3\\envs\\tf-gpu-26\\lib\\site-packages\\keras\\engine\\training.py:788 train_step\n",
      "        loss = self.compiled_loss(\n",
      "    C:\\ProgramData\\Anaconda3\\envs\\tf-gpu-26\\lib\\site-packages\\keras\\engine\\compile_utils.py:201 __call__\n",
      "        loss_value = loss_obj(y_t, y_p, sample_weight=sw)\n",
      "    C:\\ProgramData\\Anaconda3\\envs\\tf-gpu-26\\lib\\site-packages\\keras\\losses.py:141 __call__\n",
      "        losses = call_fn(y_true, y_pred)\n",
      "    C:\\ProgramData\\Anaconda3\\envs\\tf-gpu-26\\lib\\site-packages\\keras\\losses.py:245 call  **\n",
      "        return ag_fn(y_true, y_pred, **self._fn_kwargs)\n",
      "    C:\\ProgramData\\Anaconda3\\envs\\tf-gpu-26\\lib\\site-packages\\tensorflow\\python\\util\\dispatch.py:206 wrapper\n",
      "        return target(*args, **kwargs)\n",
      "    C:\\ProgramData\\Anaconda3\\envs\\tf-gpu-26\\lib\\site-packages\\keras\\losses.py:1665 categorical_crossentropy\n",
      "        return backend.categorical_crossentropy(\n",
      "    C:\\ProgramData\\Anaconda3\\envs\\tf-gpu-26\\lib\\site-packages\\tensorflow\\python\\util\\dispatch.py:206 wrapper\n",
      "        return target(*args, **kwargs)\n",
      "    C:\\ProgramData\\Anaconda3\\envs\\tf-gpu-26\\lib\\site-packages\\keras\\backend.py:4839 categorical_crossentropy\n",
      "        target.shape.assert_is_compatible_with(output.shape)\n",
      "    C:\\ProgramData\\Anaconda3\\envs\\tf-gpu-26\\lib\\site-packages\\tensorflow\\python\\framework\\tensor_shape.py:1161 assert_is_compatible_with\n",
      "        raise ValueError(\"Shapes %s and %s are incompatible\" % (self, other))\n",
      "\n",
      "    ValueError: Shapes (5, 22) and (5, 3) are incompatible\n",
      "\n",
      "\n",
      "  warnings.warn(\"Estimator fit failed. The score on this train-test\"\n"
     ]
    },
    {
     "name": "stderr",
     "output_type": "stream",
     "text": [
      "C:\\ProgramData\\Anaconda3\\envs\\tf-gpu-26\\lib\\site-packages\\sklearn\\model_selection\\_validation.py:615: FitFailedWarning: Estimator fit failed. The score on this train-test partition for these parameters will be set to nan. Details: \n",
      "Traceback (most recent call last):\n",
      "  File \"C:\\ProgramData\\Anaconda3\\envs\\tf-gpu-26\\lib\\site-packages\\sklearn\\model_selection\\_validation.py\", line 598, in _fit_and_score\n",
      "    estimator.fit(X_train, y_train, **fit_params)\n",
      "  File \"C:\\ProgramData\\Anaconda3\\envs\\tf-gpu-26\\lib\\site-packages\\keras\\wrappers\\scikit_learn.py\", line 219, in fit\n",
      "    return super(KerasClassifier, self).fit(x, y, **kwargs)\n",
      "  File \"C:\\ProgramData\\Anaconda3\\envs\\tf-gpu-26\\lib\\site-packages\\keras\\wrappers\\scikit_learn.py\", line 162, in fit\n",
      "    history = self.model.fit(x, y, **fit_args)\n",
      "  File \"C:\\ProgramData\\Anaconda3\\envs\\tf-gpu-26\\lib\\site-packages\\keras\\engine\\training.py\", line 1184, in fit\n",
      "    tmp_logs = self.train_function(iterator)\n",
      "  File \"C:\\ProgramData\\Anaconda3\\envs\\tf-gpu-26\\lib\\site-packages\\tensorflow\\python\\eager\\def_function.py\", line 885, in __call__\n",
      "    result = self._call(*args, **kwds)\n",
      "  File \"C:\\ProgramData\\Anaconda3\\envs\\tf-gpu-26\\lib\\site-packages\\tensorflow\\python\\eager\\def_function.py\", line 933, in _call\n",
      "    self._initialize(args, kwds, add_initializers_to=initializers)\n",
      "  File \"C:\\ProgramData\\Anaconda3\\envs\\tf-gpu-26\\lib\\site-packages\\tensorflow\\python\\eager\\def_function.py\", line 759, in _initialize\n",
      "    self._stateful_fn._get_concrete_function_internal_garbage_collected(  # pylint: disable=protected-access\n",
      "  File \"C:\\ProgramData\\Anaconda3\\envs\\tf-gpu-26\\lib\\site-packages\\tensorflow\\python\\eager\\function.py\", line 3066, in _get_concrete_function_internal_garbage_collected\n",
      "    graph_function, _ = self._maybe_define_function(args, kwargs)\n",
      "  File \"C:\\ProgramData\\Anaconda3\\envs\\tf-gpu-26\\lib\\site-packages\\tensorflow\\python\\eager\\function.py\", line 3463, in _maybe_define_function\n",
      "    graph_function = self._create_graph_function(args, kwargs)\n",
      "  File \"C:\\ProgramData\\Anaconda3\\envs\\tf-gpu-26\\lib\\site-packages\\tensorflow\\python\\eager\\function.py\", line 3298, in _create_graph_function\n",
      "    func_graph_module.func_graph_from_py_func(\n",
      "  File \"C:\\ProgramData\\Anaconda3\\envs\\tf-gpu-26\\lib\\site-packages\\tensorflow\\python\\framework\\func_graph.py\", line 1007, in func_graph_from_py_func\n",
      "    func_outputs = python_func(*func_args, **func_kwargs)\n",
      "  File \"C:\\ProgramData\\Anaconda3\\envs\\tf-gpu-26\\lib\\site-packages\\tensorflow\\python\\eager\\def_function.py\", line 668, in wrapped_fn\n",
      "    out = weak_wrapped_fn().__wrapped__(*args, **kwds)\n",
      "  File \"C:\\ProgramData\\Anaconda3\\envs\\tf-gpu-26\\lib\\site-packages\\tensorflow\\python\\framework\\func_graph.py\", line 994, in wrapper\n",
      "    raise e.ag_error_metadata.to_exception(e)\n",
      "ValueError: in user code:\n",
      "\n",
      "    C:\\ProgramData\\Anaconda3\\envs\\tf-gpu-26\\lib\\site-packages\\keras\\engine\\training.py:853 train_function  *\n",
      "        return step_function(self, iterator)\n",
      "    C:\\ProgramData\\Anaconda3\\envs\\tf-gpu-26\\lib\\site-packages\\keras\\engine\\training.py:842 step_function  **\n",
      "        outputs = model.distribute_strategy.run(run_step, args=(data,))\n",
      "    C:\\ProgramData\\Anaconda3\\envs\\tf-gpu-26\\lib\\site-packages\\tensorflow\\python\\distribute\\distribute_lib.py:1286 run\n",
      "        return self._extended.call_for_each_replica(fn, args=args, kwargs=kwargs)\n",
      "    C:\\ProgramData\\Anaconda3\\envs\\tf-gpu-26\\lib\\site-packages\\tensorflow\\python\\distribute\\distribute_lib.py:2849 call_for_each_replica\n",
      "        return self._call_for_each_replica(fn, args, kwargs)\n",
      "    C:\\ProgramData\\Anaconda3\\envs\\tf-gpu-26\\lib\\site-packages\\tensorflow\\python\\distribute\\distribute_lib.py:3632 _call_for_each_replica\n",
      "        return fn(*args, **kwargs)\n",
      "    C:\\ProgramData\\Anaconda3\\envs\\tf-gpu-26\\lib\\site-packages\\keras\\engine\\training.py:835 run_step  **\n",
      "        outputs = model.train_step(data)\n",
      "    C:\\ProgramData\\Anaconda3\\envs\\tf-gpu-26\\lib\\site-packages\\keras\\engine\\training.py:788 train_step\n",
      "        loss = self.compiled_loss(\n",
      "    C:\\ProgramData\\Anaconda3\\envs\\tf-gpu-26\\lib\\site-packages\\keras\\engine\\compile_utils.py:201 __call__\n",
      "        loss_value = loss_obj(y_t, y_p, sample_weight=sw)\n",
      "    C:\\ProgramData\\Anaconda3\\envs\\tf-gpu-26\\lib\\site-packages\\keras\\losses.py:141 __call__\n",
      "        losses = call_fn(y_true, y_pred)\n",
      "    C:\\ProgramData\\Anaconda3\\envs\\tf-gpu-26\\lib\\site-packages\\keras\\losses.py:245 call  **\n",
      "        return ag_fn(y_true, y_pred, **self._fn_kwargs)\n",
      "    C:\\ProgramData\\Anaconda3\\envs\\tf-gpu-26\\lib\\site-packages\\tensorflow\\python\\util\\dispatch.py:206 wrapper\n",
      "        return target(*args, **kwargs)\n",
      "    C:\\ProgramData\\Anaconda3\\envs\\tf-gpu-26\\lib\\site-packages\\keras\\losses.py:1665 categorical_crossentropy\n",
      "        return backend.categorical_crossentropy(\n",
      "    C:\\ProgramData\\Anaconda3\\envs\\tf-gpu-26\\lib\\site-packages\\tensorflow\\python\\util\\dispatch.py:206 wrapper\n",
      "        return target(*args, **kwargs)\n",
      "    C:\\ProgramData\\Anaconda3\\envs\\tf-gpu-26\\lib\\site-packages\\keras\\backend.py:4839 categorical_crossentropy\n",
      "        target.shape.assert_is_compatible_with(output.shape)\n",
      "    C:\\ProgramData\\Anaconda3\\envs\\tf-gpu-26\\lib\\site-packages\\tensorflow\\python\\framework\\tensor_shape.py:1161 assert_is_compatible_with\n",
      "        raise ValueError(\"Shapes %s and %s are incompatible\" % (self, other))\n",
      "\n",
      "    ValueError: Shapes (5, 22) and (5, 3) are incompatible\n",
      "\n",
      "\n",
      "  warnings.warn(\"Estimator fit failed. The score on this train-test\"\n",
      "C:\\ProgramData\\Anaconda3\\envs\\tf-gpu-26\\lib\\site-packages\\sklearn\\model_selection\\_validation.py:615: FitFailedWarning: Estimator fit failed. The score on this train-test partition for these parameters will be set to nan. Details: \n",
      "Traceback (most recent call last):\n",
      "  File \"C:\\ProgramData\\Anaconda3\\envs\\tf-gpu-26\\lib\\site-packages\\sklearn\\model_selection\\_validation.py\", line 598, in _fit_and_score\n",
      "    estimator.fit(X_train, y_train, **fit_params)\n",
      "  File \"C:\\ProgramData\\Anaconda3\\envs\\tf-gpu-26\\lib\\site-packages\\keras\\wrappers\\scikit_learn.py\", line 219, in fit\n",
      "    return super(KerasClassifier, self).fit(x, y, **kwargs)\n",
      "  File \"C:\\ProgramData\\Anaconda3\\envs\\tf-gpu-26\\lib\\site-packages\\keras\\wrappers\\scikit_learn.py\", line 162, in fit\n",
      "    history = self.model.fit(x, y, **fit_args)\n",
      "  File \"C:\\ProgramData\\Anaconda3\\envs\\tf-gpu-26\\lib\\site-packages\\keras\\engine\\training.py\", line 1184, in fit\n",
      "    tmp_logs = self.train_function(iterator)\n",
      "  File \"C:\\ProgramData\\Anaconda3\\envs\\tf-gpu-26\\lib\\site-packages\\tensorflow\\python\\eager\\def_function.py\", line 885, in __call__\n",
      "    result = self._call(*args, **kwds)\n",
      "  File \"C:\\ProgramData\\Anaconda3\\envs\\tf-gpu-26\\lib\\site-packages\\tensorflow\\python\\eager\\def_function.py\", line 933, in _call\n",
      "    self._initialize(args, kwds, add_initializers_to=initializers)\n",
      "  File \"C:\\ProgramData\\Anaconda3\\envs\\tf-gpu-26\\lib\\site-packages\\tensorflow\\python\\eager\\def_function.py\", line 759, in _initialize\n",
      "    self._stateful_fn._get_concrete_function_internal_garbage_collected(  # pylint: disable=protected-access\n",
      "  File \"C:\\ProgramData\\Anaconda3\\envs\\tf-gpu-26\\lib\\site-packages\\tensorflow\\python\\eager\\function.py\", line 3066, in _get_concrete_function_internal_garbage_collected\n",
      "    graph_function, _ = self._maybe_define_function(args, kwargs)\n",
      "  File \"C:\\ProgramData\\Anaconda3\\envs\\tf-gpu-26\\lib\\site-packages\\tensorflow\\python\\eager\\function.py\", line 3463, in _maybe_define_function\n",
      "    graph_function = self._create_graph_function(args, kwargs)\n",
      "  File \"C:\\ProgramData\\Anaconda3\\envs\\tf-gpu-26\\lib\\site-packages\\tensorflow\\python\\eager\\function.py\", line 3298, in _create_graph_function\n",
      "    func_graph_module.func_graph_from_py_func(\n",
      "  File \"C:\\ProgramData\\Anaconda3\\envs\\tf-gpu-26\\lib\\site-packages\\tensorflow\\python\\framework\\func_graph.py\", line 1007, in func_graph_from_py_func\n",
      "    func_outputs = python_func(*func_args, **func_kwargs)\n",
      "  File \"C:\\ProgramData\\Anaconda3\\envs\\tf-gpu-26\\lib\\site-packages\\tensorflow\\python\\eager\\def_function.py\", line 668, in wrapped_fn\n",
      "    out = weak_wrapped_fn().__wrapped__(*args, **kwds)\n",
      "  File \"C:\\ProgramData\\Anaconda3\\envs\\tf-gpu-26\\lib\\site-packages\\tensorflow\\python\\framework\\func_graph.py\", line 994, in wrapper\n",
      "    raise e.ag_error_metadata.to_exception(e)\n",
      "ValueError: in user code:\n",
      "\n",
      "    C:\\ProgramData\\Anaconda3\\envs\\tf-gpu-26\\lib\\site-packages\\keras\\engine\\training.py:853 train_function  *\n",
      "        return step_function(self, iterator)\n",
      "    C:\\ProgramData\\Anaconda3\\envs\\tf-gpu-26\\lib\\site-packages\\keras\\engine\\training.py:842 step_function  **\n",
      "        outputs = model.distribute_strategy.run(run_step, args=(data,))\n",
      "    C:\\ProgramData\\Anaconda3\\envs\\tf-gpu-26\\lib\\site-packages\\tensorflow\\python\\distribute\\distribute_lib.py:1286 run\n",
      "        return self._extended.call_for_each_replica(fn, args=args, kwargs=kwargs)\n",
      "    C:\\ProgramData\\Anaconda3\\envs\\tf-gpu-26\\lib\\site-packages\\tensorflow\\python\\distribute\\distribute_lib.py:2849 call_for_each_replica\n",
      "        return self._call_for_each_replica(fn, args, kwargs)\n",
      "    C:\\ProgramData\\Anaconda3\\envs\\tf-gpu-26\\lib\\site-packages\\tensorflow\\python\\distribute\\distribute_lib.py:3632 _call_for_each_replica\n",
      "        return fn(*args, **kwargs)\n",
      "    C:\\ProgramData\\Anaconda3\\envs\\tf-gpu-26\\lib\\site-packages\\keras\\engine\\training.py:835 run_step  **\n",
      "        outputs = model.train_step(data)\n",
      "    C:\\ProgramData\\Anaconda3\\envs\\tf-gpu-26\\lib\\site-packages\\keras\\engine\\training.py:788 train_step\n",
      "        loss = self.compiled_loss(\n",
      "    C:\\ProgramData\\Anaconda3\\envs\\tf-gpu-26\\lib\\site-packages\\keras\\engine\\compile_utils.py:201 __call__\n",
      "        loss_value = loss_obj(y_t, y_p, sample_weight=sw)\n",
      "    C:\\ProgramData\\Anaconda3\\envs\\tf-gpu-26\\lib\\site-packages\\keras\\losses.py:141 __call__\n",
      "        losses = call_fn(y_true, y_pred)\n",
      "    C:\\ProgramData\\Anaconda3\\envs\\tf-gpu-26\\lib\\site-packages\\keras\\losses.py:245 call  **\n",
      "        return ag_fn(y_true, y_pred, **self._fn_kwargs)\n",
      "    C:\\ProgramData\\Anaconda3\\envs\\tf-gpu-26\\lib\\site-packages\\tensorflow\\python\\util\\dispatch.py:206 wrapper\n",
      "        return target(*args, **kwargs)\n",
      "    C:\\ProgramData\\Anaconda3\\envs\\tf-gpu-26\\lib\\site-packages\\keras\\losses.py:1665 categorical_crossentropy\n",
      "        return backend.categorical_crossentropy(\n",
      "    C:\\ProgramData\\Anaconda3\\envs\\tf-gpu-26\\lib\\site-packages\\tensorflow\\python\\util\\dispatch.py:206 wrapper\n",
      "        return target(*args, **kwargs)\n",
      "    C:\\ProgramData\\Anaconda3\\envs\\tf-gpu-26\\lib\\site-packages\\keras\\backend.py:4839 categorical_crossentropy\n",
      "        target.shape.assert_is_compatible_with(output.shape)\n",
      "    C:\\ProgramData\\Anaconda3\\envs\\tf-gpu-26\\lib\\site-packages\\tensorflow\\python\\framework\\tensor_shape.py:1161 assert_is_compatible_with\n",
      "        raise ValueError(\"Shapes %s and %s are incompatible\" % (self, other))\n",
      "\n",
      "    ValueError: Shapes (5, 22) and (5, 3) are incompatible\n",
      "\n",
      "\n",
      "  warnings.warn(\"Estimator fit failed. The score on this train-test\"\n",
      "C:\\ProgramData\\Anaconda3\\envs\\tf-gpu-26\\lib\\site-packages\\sklearn\\model_selection\\_validation.py:615: FitFailedWarning: Estimator fit failed. The score on this train-test partition for these parameters will be set to nan. Details: \n",
      "Traceback (most recent call last):\n",
      "  File \"C:\\ProgramData\\Anaconda3\\envs\\tf-gpu-26\\lib\\site-packages\\sklearn\\model_selection\\_validation.py\", line 598, in _fit_and_score\n",
      "    estimator.fit(X_train, y_train, **fit_params)\n",
      "  File \"C:\\ProgramData\\Anaconda3\\envs\\tf-gpu-26\\lib\\site-packages\\keras\\wrappers\\scikit_learn.py\", line 219, in fit\n",
      "    return super(KerasClassifier, self).fit(x, y, **kwargs)\n",
      "  File \"C:\\ProgramData\\Anaconda3\\envs\\tf-gpu-26\\lib\\site-packages\\keras\\wrappers\\scikit_learn.py\", line 162, in fit\n",
      "    history = self.model.fit(x, y, **fit_args)\n",
      "  File \"C:\\ProgramData\\Anaconda3\\envs\\tf-gpu-26\\lib\\site-packages\\keras\\engine\\training.py\", line 1184, in fit\n",
      "    tmp_logs = self.train_function(iterator)\n",
      "  File \"C:\\ProgramData\\Anaconda3\\envs\\tf-gpu-26\\lib\\site-packages\\tensorflow\\python\\eager\\def_function.py\", line 885, in __call__\n",
      "    result = self._call(*args, **kwds)\n",
      "  File \"C:\\ProgramData\\Anaconda3\\envs\\tf-gpu-26\\lib\\site-packages\\tensorflow\\python\\eager\\def_function.py\", line 933, in _call\n",
      "    self._initialize(args, kwds, add_initializers_to=initializers)\n",
      "  File \"C:\\ProgramData\\Anaconda3\\envs\\tf-gpu-26\\lib\\site-packages\\tensorflow\\python\\eager\\def_function.py\", line 759, in _initialize\n",
      "    self._stateful_fn._get_concrete_function_internal_garbage_collected(  # pylint: disable=protected-access\n",
      "  File \"C:\\ProgramData\\Anaconda3\\envs\\tf-gpu-26\\lib\\site-packages\\tensorflow\\python\\eager\\function.py\", line 3066, in _get_concrete_function_internal_garbage_collected\n",
      "    graph_function, _ = self._maybe_define_function(args, kwargs)\n",
      "  File \"C:\\ProgramData\\Anaconda3\\envs\\tf-gpu-26\\lib\\site-packages\\tensorflow\\python\\eager\\function.py\", line 3463, in _maybe_define_function\n",
      "    graph_function = self._create_graph_function(args, kwargs)\n",
      "  File \"C:\\ProgramData\\Anaconda3\\envs\\tf-gpu-26\\lib\\site-packages\\tensorflow\\python\\eager\\function.py\", line 3298, in _create_graph_function\n",
      "    func_graph_module.func_graph_from_py_func(\n",
      "  File \"C:\\ProgramData\\Anaconda3\\envs\\tf-gpu-26\\lib\\site-packages\\tensorflow\\python\\framework\\func_graph.py\", line 1007, in func_graph_from_py_func\n",
      "    func_outputs = python_func(*func_args, **func_kwargs)\n",
      "  File \"C:\\ProgramData\\Anaconda3\\envs\\tf-gpu-26\\lib\\site-packages\\tensorflow\\python\\eager\\def_function.py\", line 668, in wrapped_fn\n",
      "    out = weak_wrapped_fn().__wrapped__(*args, **kwds)\n",
      "  File \"C:\\ProgramData\\Anaconda3\\envs\\tf-gpu-26\\lib\\site-packages\\tensorflow\\python\\framework\\func_graph.py\", line 994, in wrapper\n",
      "    raise e.ag_error_metadata.to_exception(e)\n",
      "ValueError: in user code:\n",
      "\n",
      "    C:\\ProgramData\\Anaconda3\\envs\\tf-gpu-26\\lib\\site-packages\\keras\\engine\\training.py:853 train_function  *\n",
      "        return step_function(self, iterator)\n",
      "    C:\\ProgramData\\Anaconda3\\envs\\tf-gpu-26\\lib\\site-packages\\keras\\engine\\training.py:842 step_function  **\n",
      "        outputs = model.distribute_strategy.run(run_step, args=(data,))\n",
      "    C:\\ProgramData\\Anaconda3\\envs\\tf-gpu-26\\lib\\site-packages\\tensorflow\\python\\distribute\\distribute_lib.py:1286 run\n",
      "        return self._extended.call_for_each_replica(fn, args=args, kwargs=kwargs)\n",
      "    C:\\ProgramData\\Anaconda3\\envs\\tf-gpu-26\\lib\\site-packages\\tensorflow\\python\\distribute\\distribute_lib.py:2849 call_for_each_replica\n",
      "        return self._call_for_each_replica(fn, args, kwargs)\n",
      "    C:\\ProgramData\\Anaconda3\\envs\\tf-gpu-26\\lib\\site-packages\\tensorflow\\python\\distribute\\distribute_lib.py:3632 _call_for_each_replica\n",
      "        return fn(*args, **kwargs)\n",
      "    C:\\ProgramData\\Anaconda3\\envs\\tf-gpu-26\\lib\\site-packages\\keras\\engine\\training.py:835 run_step  **\n",
      "        outputs = model.train_step(data)\n",
      "    C:\\ProgramData\\Anaconda3\\envs\\tf-gpu-26\\lib\\site-packages\\keras\\engine\\training.py:788 train_step\n",
      "        loss = self.compiled_loss(\n",
      "    C:\\ProgramData\\Anaconda3\\envs\\tf-gpu-26\\lib\\site-packages\\keras\\engine\\compile_utils.py:201 __call__\n",
      "        loss_value = loss_obj(y_t, y_p, sample_weight=sw)\n",
      "    C:\\ProgramData\\Anaconda3\\envs\\tf-gpu-26\\lib\\site-packages\\keras\\losses.py:141 __call__\n",
      "        losses = call_fn(y_true, y_pred)\n",
      "    C:\\ProgramData\\Anaconda3\\envs\\tf-gpu-26\\lib\\site-packages\\keras\\losses.py:245 call  **\n",
      "        return ag_fn(y_true, y_pred, **self._fn_kwargs)\n",
      "    C:\\ProgramData\\Anaconda3\\envs\\tf-gpu-26\\lib\\site-packages\\tensorflow\\python\\util\\dispatch.py:206 wrapper\n",
      "        return target(*args, **kwargs)\n",
      "    C:\\ProgramData\\Anaconda3\\envs\\tf-gpu-26\\lib\\site-packages\\keras\\losses.py:1665 categorical_crossentropy\n",
      "        return backend.categorical_crossentropy(\n",
      "    C:\\ProgramData\\Anaconda3\\envs\\tf-gpu-26\\lib\\site-packages\\tensorflow\\python\\util\\dispatch.py:206 wrapper\n",
      "        return target(*args, **kwargs)\n",
      "    C:\\ProgramData\\Anaconda3\\envs\\tf-gpu-26\\lib\\site-packages\\keras\\backend.py:4839 categorical_crossentropy\n",
      "        target.shape.assert_is_compatible_with(output.shape)\n",
      "    C:\\ProgramData\\Anaconda3\\envs\\tf-gpu-26\\lib\\site-packages\\tensorflow\\python\\framework\\tensor_shape.py:1161 assert_is_compatible_with\n",
      "        raise ValueError(\"Shapes %s and %s are incompatible\" % (self, other))\n",
      "\n",
      "    ValueError: Shapes (5, 22) and (5, 3) are incompatible\n",
      "\n",
      "\n",
      "  warnings.warn(\"Estimator fit failed. The score on this train-test\"\n"
     ]
    },
    {
     "name": "stderr",
     "output_type": "stream",
     "text": [
      "C:\\ProgramData\\Anaconda3\\envs\\tf-gpu-26\\lib\\site-packages\\sklearn\\model_selection\\_validation.py:615: FitFailedWarning: Estimator fit failed. The score on this train-test partition for these parameters will be set to nan. Details: \n",
      "Traceback (most recent call last):\n",
      "  File \"C:\\ProgramData\\Anaconda3\\envs\\tf-gpu-26\\lib\\site-packages\\sklearn\\model_selection\\_validation.py\", line 598, in _fit_and_score\n",
      "    estimator.fit(X_train, y_train, **fit_params)\n",
      "  File \"C:\\ProgramData\\Anaconda3\\envs\\tf-gpu-26\\lib\\site-packages\\keras\\wrappers\\scikit_learn.py\", line 219, in fit\n",
      "    return super(KerasClassifier, self).fit(x, y, **kwargs)\n",
      "  File \"C:\\ProgramData\\Anaconda3\\envs\\tf-gpu-26\\lib\\site-packages\\keras\\wrappers\\scikit_learn.py\", line 162, in fit\n",
      "    history = self.model.fit(x, y, **fit_args)\n",
      "  File \"C:\\ProgramData\\Anaconda3\\envs\\tf-gpu-26\\lib\\site-packages\\keras\\engine\\training.py\", line 1184, in fit\n",
      "    tmp_logs = self.train_function(iterator)\n",
      "  File \"C:\\ProgramData\\Anaconda3\\envs\\tf-gpu-26\\lib\\site-packages\\tensorflow\\python\\eager\\def_function.py\", line 885, in __call__\n",
      "    result = self._call(*args, **kwds)\n",
      "  File \"C:\\ProgramData\\Anaconda3\\envs\\tf-gpu-26\\lib\\site-packages\\tensorflow\\python\\eager\\def_function.py\", line 933, in _call\n",
      "    self._initialize(args, kwds, add_initializers_to=initializers)\n",
      "  File \"C:\\ProgramData\\Anaconda3\\envs\\tf-gpu-26\\lib\\site-packages\\tensorflow\\python\\eager\\def_function.py\", line 759, in _initialize\n",
      "    self._stateful_fn._get_concrete_function_internal_garbage_collected(  # pylint: disable=protected-access\n",
      "  File \"C:\\ProgramData\\Anaconda3\\envs\\tf-gpu-26\\lib\\site-packages\\tensorflow\\python\\eager\\function.py\", line 3066, in _get_concrete_function_internal_garbage_collected\n",
      "    graph_function, _ = self._maybe_define_function(args, kwargs)\n",
      "  File \"C:\\ProgramData\\Anaconda3\\envs\\tf-gpu-26\\lib\\site-packages\\tensorflow\\python\\eager\\function.py\", line 3463, in _maybe_define_function\n",
      "    graph_function = self._create_graph_function(args, kwargs)\n",
      "  File \"C:\\ProgramData\\Anaconda3\\envs\\tf-gpu-26\\lib\\site-packages\\tensorflow\\python\\eager\\function.py\", line 3298, in _create_graph_function\n",
      "    func_graph_module.func_graph_from_py_func(\n",
      "  File \"C:\\ProgramData\\Anaconda3\\envs\\tf-gpu-26\\lib\\site-packages\\tensorflow\\python\\framework\\func_graph.py\", line 1007, in func_graph_from_py_func\n",
      "    func_outputs = python_func(*func_args, **func_kwargs)\n",
      "  File \"C:\\ProgramData\\Anaconda3\\envs\\tf-gpu-26\\lib\\site-packages\\tensorflow\\python\\eager\\def_function.py\", line 668, in wrapped_fn\n",
      "    out = weak_wrapped_fn().__wrapped__(*args, **kwds)\n",
      "  File \"C:\\ProgramData\\Anaconda3\\envs\\tf-gpu-26\\lib\\site-packages\\tensorflow\\python\\framework\\func_graph.py\", line 994, in wrapper\n",
      "    raise e.ag_error_metadata.to_exception(e)\n",
      "ValueError: in user code:\n",
      "\n",
      "    C:\\ProgramData\\Anaconda3\\envs\\tf-gpu-26\\lib\\site-packages\\keras\\engine\\training.py:853 train_function  *\n",
      "        return step_function(self, iterator)\n",
      "    C:\\ProgramData\\Anaconda3\\envs\\tf-gpu-26\\lib\\site-packages\\keras\\engine\\training.py:842 step_function  **\n",
      "        outputs = model.distribute_strategy.run(run_step, args=(data,))\n",
      "    C:\\ProgramData\\Anaconda3\\envs\\tf-gpu-26\\lib\\site-packages\\tensorflow\\python\\distribute\\distribute_lib.py:1286 run\n",
      "        return self._extended.call_for_each_replica(fn, args=args, kwargs=kwargs)\n",
      "    C:\\ProgramData\\Anaconda3\\envs\\tf-gpu-26\\lib\\site-packages\\tensorflow\\python\\distribute\\distribute_lib.py:2849 call_for_each_replica\n",
      "        return self._call_for_each_replica(fn, args, kwargs)\n",
      "    C:\\ProgramData\\Anaconda3\\envs\\tf-gpu-26\\lib\\site-packages\\tensorflow\\python\\distribute\\distribute_lib.py:3632 _call_for_each_replica\n",
      "        return fn(*args, **kwargs)\n",
      "    C:\\ProgramData\\Anaconda3\\envs\\tf-gpu-26\\lib\\site-packages\\keras\\engine\\training.py:835 run_step  **\n",
      "        outputs = model.train_step(data)\n",
      "    C:\\ProgramData\\Anaconda3\\envs\\tf-gpu-26\\lib\\site-packages\\keras\\engine\\training.py:788 train_step\n",
      "        loss = self.compiled_loss(\n",
      "    C:\\ProgramData\\Anaconda3\\envs\\tf-gpu-26\\lib\\site-packages\\keras\\engine\\compile_utils.py:201 __call__\n",
      "        loss_value = loss_obj(y_t, y_p, sample_weight=sw)\n",
      "    C:\\ProgramData\\Anaconda3\\envs\\tf-gpu-26\\lib\\site-packages\\keras\\losses.py:141 __call__\n",
      "        losses = call_fn(y_true, y_pred)\n",
      "    C:\\ProgramData\\Anaconda3\\envs\\tf-gpu-26\\lib\\site-packages\\keras\\losses.py:245 call  **\n",
      "        return ag_fn(y_true, y_pred, **self._fn_kwargs)\n",
      "    C:\\ProgramData\\Anaconda3\\envs\\tf-gpu-26\\lib\\site-packages\\tensorflow\\python\\util\\dispatch.py:206 wrapper\n",
      "        return target(*args, **kwargs)\n",
      "    C:\\ProgramData\\Anaconda3\\envs\\tf-gpu-26\\lib\\site-packages\\keras\\losses.py:1665 categorical_crossentropy\n",
      "        return backend.categorical_crossentropy(\n",
      "    C:\\ProgramData\\Anaconda3\\envs\\tf-gpu-26\\lib\\site-packages\\tensorflow\\python\\util\\dispatch.py:206 wrapper\n",
      "        return target(*args, **kwargs)\n",
      "    C:\\ProgramData\\Anaconda3\\envs\\tf-gpu-26\\lib\\site-packages\\keras\\backend.py:4839 categorical_crossentropy\n",
      "        target.shape.assert_is_compatible_with(output.shape)\n",
      "    C:\\ProgramData\\Anaconda3\\envs\\tf-gpu-26\\lib\\site-packages\\tensorflow\\python\\framework\\tensor_shape.py:1161 assert_is_compatible_with\n",
      "        raise ValueError(\"Shapes %s and %s are incompatible\" % (self, other))\n",
      "\n",
      "    ValueError: Shapes (5, 22) and (5, 3) are incompatible\n",
      "\n",
      "\n",
      "  warnings.warn(\"Estimator fit failed. The score on this train-test\"\n",
      "C:\\ProgramData\\Anaconda3\\envs\\tf-gpu-26\\lib\\site-packages\\sklearn\\model_selection\\_validation.py:615: FitFailedWarning: Estimator fit failed. The score on this train-test partition for these parameters will be set to nan. Details: \n",
      "Traceback (most recent call last):\n",
      "  File \"C:\\ProgramData\\Anaconda3\\envs\\tf-gpu-26\\lib\\site-packages\\sklearn\\model_selection\\_validation.py\", line 598, in _fit_and_score\n",
      "    estimator.fit(X_train, y_train, **fit_params)\n",
      "  File \"C:\\ProgramData\\Anaconda3\\envs\\tf-gpu-26\\lib\\site-packages\\keras\\wrappers\\scikit_learn.py\", line 219, in fit\n",
      "    return super(KerasClassifier, self).fit(x, y, **kwargs)\n",
      "  File \"C:\\ProgramData\\Anaconda3\\envs\\tf-gpu-26\\lib\\site-packages\\keras\\wrappers\\scikit_learn.py\", line 162, in fit\n",
      "    history = self.model.fit(x, y, **fit_args)\n",
      "  File \"C:\\ProgramData\\Anaconda3\\envs\\tf-gpu-26\\lib\\site-packages\\keras\\engine\\training.py\", line 1184, in fit\n",
      "    tmp_logs = self.train_function(iterator)\n",
      "  File \"C:\\ProgramData\\Anaconda3\\envs\\tf-gpu-26\\lib\\site-packages\\tensorflow\\python\\eager\\def_function.py\", line 885, in __call__\n",
      "    result = self._call(*args, **kwds)\n",
      "  File \"C:\\ProgramData\\Anaconda3\\envs\\tf-gpu-26\\lib\\site-packages\\tensorflow\\python\\eager\\def_function.py\", line 933, in _call\n",
      "    self._initialize(args, kwds, add_initializers_to=initializers)\n",
      "  File \"C:\\ProgramData\\Anaconda3\\envs\\tf-gpu-26\\lib\\site-packages\\tensorflow\\python\\eager\\def_function.py\", line 759, in _initialize\n",
      "    self._stateful_fn._get_concrete_function_internal_garbage_collected(  # pylint: disable=protected-access\n",
      "  File \"C:\\ProgramData\\Anaconda3\\envs\\tf-gpu-26\\lib\\site-packages\\tensorflow\\python\\eager\\function.py\", line 3066, in _get_concrete_function_internal_garbage_collected\n",
      "    graph_function, _ = self._maybe_define_function(args, kwargs)\n",
      "  File \"C:\\ProgramData\\Anaconda3\\envs\\tf-gpu-26\\lib\\site-packages\\tensorflow\\python\\eager\\function.py\", line 3463, in _maybe_define_function\n",
      "    graph_function = self._create_graph_function(args, kwargs)\n",
      "  File \"C:\\ProgramData\\Anaconda3\\envs\\tf-gpu-26\\lib\\site-packages\\tensorflow\\python\\eager\\function.py\", line 3298, in _create_graph_function\n",
      "    func_graph_module.func_graph_from_py_func(\n",
      "  File \"C:\\ProgramData\\Anaconda3\\envs\\tf-gpu-26\\lib\\site-packages\\tensorflow\\python\\framework\\func_graph.py\", line 1007, in func_graph_from_py_func\n",
      "    func_outputs = python_func(*func_args, **func_kwargs)\n",
      "  File \"C:\\ProgramData\\Anaconda3\\envs\\tf-gpu-26\\lib\\site-packages\\tensorflow\\python\\eager\\def_function.py\", line 668, in wrapped_fn\n",
      "    out = weak_wrapped_fn().__wrapped__(*args, **kwds)\n",
      "  File \"C:\\ProgramData\\Anaconda3\\envs\\tf-gpu-26\\lib\\site-packages\\tensorflow\\python\\framework\\func_graph.py\", line 994, in wrapper\n",
      "    raise e.ag_error_metadata.to_exception(e)\n",
      "ValueError: in user code:\n",
      "\n",
      "    C:\\ProgramData\\Anaconda3\\envs\\tf-gpu-26\\lib\\site-packages\\keras\\engine\\training.py:853 train_function  *\n",
      "        return step_function(self, iterator)\n",
      "    C:\\ProgramData\\Anaconda3\\envs\\tf-gpu-26\\lib\\site-packages\\keras\\engine\\training.py:842 step_function  **\n",
      "        outputs = model.distribute_strategy.run(run_step, args=(data,))\n",
      "    C:\\ProgramData\\Anaconda3\\envs\\tf-gpu-26\\lib\\site-packages\\tensorflow\\python\\distribute\\distribute_lib.py:1286 run\n",
      "        return self._extended.call_for_each_replica(fn, args=args, kwargs=kwargs)\n",
      "    C:\\ProgramData\\Anaconda3\\envs\\tf-gpu-26\\lib\\site-packages\\tensorflow\\python\\distribute\\distribute_lib.py:2849 call_for_each_replica\n",
      "        return self._call_for_each_replica(fn, args, kwargs)\n",
      "    C:\\ProgramData\\Anaconda3\\envs\\tf-gpu-26\\lib\\site-packages\\tensorflow\\python\\distribute\\distribute_lib.py:3632 _call_for_each_replica\n",
      "        return fn(*args, **kwargs)\n",
      "    C:\\ProgramData\\Anaconda3\\envs\\tf-gpu-26\\lib\\site-packages\\keras\\engine\\training.py:835 run_step  **\n",
      "        outputs = model.train_step(data)\n",
      "    C:\\ProgramData\\Anaconda3\\envs\\tf-gpu-26\\lib\\site-packages\\keras\\engine\\training.py:788 train_step\n",
      "        loss = self.compiled_loss(\n",
      "    C:\\ProgramData\\Anaconda3\\envs\\tf-gpu-26\\lib\\site-packages\\keras\\engine\\compile_utils.py:201 __call__\n",
      "        loss_value = loss_obj(y_t, y_p, sample_weight=sw)\n",
      "    C:\\ProgramData\\Anaconda3\\envs\\tf-gpu-26\\lib\\site-packages\\keras\\losses.py:141 __call__\n",
      "        losses = call_fn(y_true, y_pred)\n",
      "    C:\\ProgramData\\Anaconda3\\envs\\tf-gpu-26\\lib\\site-packages\\keras\\losses.py:245 call  **\n",
      "        return ag_fn(y_true, y_pred, **self._fn_kwargs)\n",
      "    C:\\ProgramData\\Anaconda3\\envs\\tf-gpu-26\\lib\\site-packages\\tensorflow\\python\\util\\dispatch.py:206 wrapper\n",
      "        return target(*args, **kwargs)\n",
      "    C:\\ProgramData\\Anaconda3\\envs\\tf-gpu-26\\lib\\site-packages\\keras\\losses.py:1665 categorical_crossentropy\n",
      "        return backend.categorical_crossentropy(\n",
      "    C:\\ProgramData\\Anaconda3\\envs\\tf-gpu-26\\lib\\site-packages\\tensorflow\\python\\util\\dispatch.py:206 wrapper\n",
      "        return target(*args, **kwargs)\n",
      "    C:\\ProgramData\\Anaconda3\\envs\\tf-gpu-26\\lib\\site-packages\\keras\\backend.py:4839 categorical_crossentropy\n",
      "        target.shape.assert_is_compatible_with(output.shape)\n",
      "    C:\\ProgramData\\Anaconda3\\envs\\tf-gpu-26\\lib\\site-packages\\tensorflow\\python\\framework\\tensor_shape.py:1161 assert_is_compatible_with\n",
      "        raise ValueError(\"Shapes %s and %s are incompatible\" % (self, other))\n",
      "\n",
      "    ValueError: Shapes (5, 22) and (5, 3) are incompatible\n",
      "\n",
      "\n",
      "  warnings.warn(\"Estimator fit failed. The score on this train-test\"\n",
      "C:\\ProgramData\\Anaconda3\\envs\\tf-gpu-26\\lib\\site-packages\\sklearn\\model_selection\\_validation.py:615: FitFailedWarning: Estimator fit failed. The score on this train-test partition for these parameters will be set to nan. Details: \n",
      "Traceback (most recent call last):\n",
      "  File \"C:\\ProgramData\\Anaconda3\\envs\\tf-gpu-26\\lib\\site-packages\\sklearn\\model_selection\\_validation.py\", line 598, in _fit_and_score\n",
      "    estimator.fit(X_train, y_train, **fit_params)\n",
      "  File \"C:\\ProgramData\\Anaconda3\\envs\\tf-gpu-26\\lib\\site-packages\\keras\\wrappers\\scikit_learn.py\", line 219, in fit\n",
      "    return super(KerasClassifier, self).fit(x, y, **kwargs)\n",
      "  File \"C:\\ProgramData\\Anaconda3\\envs\\tf-gpu-26\\lib\\site-packages\\keras\\wrappers\\scikit_learn.py\", line 162, in fit\n",
      "    history = self.model.fit(x, y, **fit_args)\n",
      "  File \"C:\\ProgramData\\Anaconda3\\envs\\tf-gpu-26\\lib\\site-packages\\keras\\engine\\training.py\", line 1184, in fit\n",
      "    tmp_logs = self.train_function(iterator)\n",
      "  File \"C:\\ProgramData\\Anaconda3\\envs\\tf-gpu-26\\lib\\site-packages\\tensorflow\\python\\eager\\def_function.py\", line 885, in __call__\n",
      "    result = self._call(*args, **kwds)\n",
      "  File \"C:\\ProgramData\\Anaconda3\\envs\\tf-gpu-26\\lib\\site-packages\\tensorflow\\python\\eager\\def_function.py\", line 933, in _call\n",
      "    self._initialize(args, kwds, add_initializers_to=initializers)\n",
      "  File \"C:\\ProgramData\\Anaconda3\\envs\\tf-gpu-26\\lib\\site-packages\\tensorflow\\python\\eager\\def_function.py\", line 759, in _initialize\n",
      "    self._stateful_fn._get_concrete_function_internal_garbage_collected(  # pylint: disable=protected-access\n",
      "  File \"C:\\ProgramData\\Anaconda3\\envs\\tf-gpu-26\\lib\\site-packages\\tensorflow\\python\\eager\\function.py\", line 3066, in _get_concrete_function_internal_garbage_collected\n",
      "    graph_function, _ = self._maybe_define_function(args, kwargs)\n",
      "  File \"C:\\ProgramData\\Anaconda3\\envs\\tf-gpu-26\\lib\\site-packages\\tensorflow\\python\\eager\\function.py\", line 3463, in _maybe_define_function\n",
      "    graph_function = self._create_graph_function(args, kwargs)\n",
      "  File \"C:\\ProgramData\\Anaconda3\\envs\\tf-gpu-26\\lib\\site-packages\\tensorflow\\python\\eager\\function.py\", line 3298, in _create_graph_function\n",
      "    func_graph_module.func_graph_from_py_func(\n",
      "  File \"C:\\ProgramData\\Anaconda3\\envs\\tf-gpu-26\\lib\\site-packages\\tensorflow\\python\\framework\\func_graph.py\", line 1007, in func_graph_from_py_func\n",
      "    func_outputs = python_func(*func_args, **func_kwargs)\n",
      "  File \"C:\\ProgramData\\Anaconda3\\envs\\tf-gpu-26\\lib\\site-packages\\tensorflow\\python\\eager\\def_function.py\", line 668, in wrapped_fn\n",
      "    out = weak_wrapped_fn().__wrapped__(*args, **kwds)\n",
      "  File \"C:\\ProgramData\\Anaconda3\\envs\\tf-gpu-26\\lib\\site-packages\\tensorflow\\python\\framework\\func_graph.py\", line 994, in wrapper\n",
      "    raise e.ag_error_metadata.to_exception(e)\n",
      "ValueError: in user code:\n",
      "\n",
      "    C:\\ProgramData\\Anaconda3\\envs\\tf-gpu-26\\lib\\site-packages\\keras\\engine\\training.py:853 train_function  *\n",
      "        return step_function(self, iterator)\n",
      "    C:\\ProgramData\\Anaconda3\\envs\\tf-gpu-26\\lib\\site-packages\\keras\\engine\\training.py:842 step_function  **\n",
      "        outputs = model.distribute_strategy.run(run_step, args=(data,))\n",
      "    C:\\ProgramData\\Anaconda3\\envs\\tf-gpu-26\\lib\\site-packages\\tensorflow\\python\\distribute\\distribute_lib.py:1286 run\n",
      "        return self._extended.call_for_each_replica(fn, args=args, kwargs=kwargs)\n",
      "    C:\\ProgramData\\Anaconda3\\envs\\tf-gpu-26\\lib\\site-packages\\tensorflow\\python\\distribute\\distribute_lib.py:2849 call_for_each_replica\n",
      "        return self._call_for_each_replica(fn, args, kwargs)\n",
      "    C:\\ProgramData\\Anaconda3\\envs\\tf-gpu-26\\lib\\site-packages\\tensorflow\\python\\distribute\\distribute_lib.py:3632 _call_for_each_replica\n",
      "        return fn(*args, **kwargs)\n",
      "    C:\\ProgramData\\Anaconda3\\envs\\tf-gpu-26\\lib\\site-packages\\keras\\engine\\training.py:835 run_step  **\n",
      "        outputs = model.train_step(data)\n",
      "    C:\\ProgramData\\Anaconda3\\envs\\tf-gpu-26\\lib\\site-packages\\keras\\engine\\training.py:788 train_step\n",
      "        loss = self.compiled_loss(\n",
      "    C:\\ProgramData\\Anaconda3\\envs\\tf-gpu-26\\lib\\site-packages\\keras\\engine\\compile_utils.py:201 __call__\n",
      "        loss_value = loss_obj(y_t, y_p, sample_weight=sw)\n",
      "    C:\\ProgramData\\Anaconda3\\envs\\tf-gpu-26\\lib\\site-packages\\keras\\losses.py:141 __call__\n",
      "        losses = call_fn(y_true, y_pred)\n",
      "    C:\\ProgramData\\Anaconda3\\envs\\tf-gpu-26\\lib\\site-packages\\keras\\losses.py:245 call  **\n",
      "        return ag_fn(y_true, y_pred, **self._fn_kwargs)\n",
      "    C:\\ProgramData\\Anaconda3\\envs\\tf-gpu-26\\lib\\site-packages\\tensorflow\\python\\util\\dispatch.py:206 wrapper\n",
      "        return target(*args, **kwargs)\n",
      "    C:\\ProgramData\\Anaconda3\\envs\\tf-gpu-26\\lib\\site-packages\\keras\\losses.py:1665 categorical_crossentropy\n",
      "        return backend.categorical_crossentropy(\n",
      "    C:\\ProgramData\\Anaconda3\\envs\\tf-gpu-26\\lib\\site-packages\\tensorflow\\python\\util\\dispatch.py:206 wrapper\n",
      "        return target(*args, **kwargs)\n",
      "    C:\\ProgramData\\Anaconda3\\envs\\tf-gpu-26\\lib\\site-packages\\keras\\backend.py:4839 categorical_crossentropy\n",
      "        target.shape.assert_is_compatible_with(output.shape)\n",
      "    C:\\ProgramData\\Anaconda3\\envs\\tf-gpu-26\\lib\\site-packages\\tensorflow\\python\\framework\\tensor_shape.py:1161 assert_is_compatible_with\n",
      "        raise ValueError(\"Shapes %s and %s are incompatible\" % (self, other))\n",
      "\n",
      "    ValueError: Shapes (5, 22) and (5, 3) are incompatible\n",
      "\n",
      "\n",
      "  warnings.warn(\"Estimator fit failed. The score on this train-test\"\n"
     ]
    },
    {
     "name": "stdout",
     "output_type": "stream",
     "text": [
      "Baseline: nan% (nan%)\n"
     ]
    },
    {
     "name": "stderr",
     "output_type": "stream",
     "text": [
      "C:\\ProgramData\\Anaconda3\\envs\\tf-gpu-26\\lib\\site-packages\\sklearn\\model_selection\\_validation.py:615: FitFailedWarning: Estimator fit failed. The score on this train-test partition for these parameters will be set to nan. Details: \n",
      "Traceback (most recent call last):\n",
      "  File \"C:\\ProgramData\\Anaconda3\\envs\\tf-gpu-26\\lib\\site-packages\\sklearn\\model_selection\\_validation.py\", line 598, in _fit_and_score\n",
      "    estimator.fit(X_train, y_train, **fit_params)\n",
      "  File \"C:\\ProgramData\\Anaconda3\\envs\\tf-gpu-26\\lib\\site-packages\\keras\\wrappers\\scikit_learn.py\", line 219, in fit\n",
      "    return super(KerasClassifier, self).fit(x, y, **kwargs)\n",
      "  File \"C:\\ProgramData\\Anaconda3\\envs\\tf-gpu-26\\lib\\site-packages\\keras\\wrappers\\scikit_learn.py\", line 162, in fit\n",
      "    history = self.model.fit(x, y, **fit_args)\n",
      "  File \"C:\\ProgramData\\Anaconda3\\envs\\tf-gpu-26\\lib\\site-packages\\keras\\engine\\training.py\", line 1184, in fit\n",
      "    tmp_logs = self.train_function(iterator)\n",
      "  File \"C:\\ProgramData\\Anaconda3\\envs\\tf-gpu-26\\lib\\site-packages\\tensorflow\\python\\eager\\def_function.py\", line 885, in __call__\n",
      "    result = self._call(*args, **kwds)\n",
      "  File \"C:\\ProgramData\\Anaconda3\\envs\\tf-gpu-26\\lib\\site-packages\\tensorflow\\python\\eager\\def_function.py\", line 933, in _call\n",
      "    self._initialize(args, kwds, add_initializers_to=initializers)\n",
      "  File \"C:\\ProgramData\\Anaconda3\\envs\\tf-gpu-26\\lib\\site-packages\\tensorflow\\python\\eager\\def_function.py\", line 759, in _initialize\n",
      "    self._stateful_fn._get_concrete_function_internal_garbage_collected(  # pylint: disable=protected-access\n",
      "  File \"C:\\ProgramData\\Anaconda3\\envs\\tf-gpu-26\\lib\\site-packages\\tensorflow\\python\\eager\\function.py\", line 3066, in _get_concrete_function_internal_garbage_collected\n",
      "    graph_function, _ = self._maybe_define_function(args, kwargs)\n",
      "  File \"C:\\ProgramData\\Anaconda3\\envs\\tf-gpu-26\\lib\\site-packages\\tensorflow\\python\\eager\\function.py\", line 3463, in _maybe_define_function\n",
      "    graph_function = self._create_graph_function(args, kwargs)\n",
      "  File \"C:\\ProgramData\\Anaconda3\\envs\\tf-gpu-26\\lib\\site-packages\\tensorflow\\python\\eager\\function.py\", line 3298, in _create_graph_function\n",
      "    func_graph_module.func_graph_from_py_func(\n",
      "  File \"C:\\ProgramData\\Anaconda3\\envs\\tf-gpu-26\\lib\\site-packages\\tensorflow\\python\\framework\\func_graph.py\", line 1007, in func_graph_from_py_func\n",
      "    func_outputs = python_func(*func_args, **func_kwargs)\n",
      "  File \"C:\\ProgramData\\Anaconda3\\envs\\tf-gpu-26\\lib\\site-packages\\tensorflow\\python\\eager\\def_function.py\", line 668, in wrapped_fn\n",
      "    out = weak_wrapped_fn().__wrapped__(*args, **kwds)\n",
      "  File \"C:\\ProgramData\\Anaconda3\\envs\\tf-gpu-26\\lib\\site-packages\\tensorflow\\python\\framework\\func_graph.py\", line 994, in wrapper\n",
      "    raise e.ag_error_metadata.to_exception(e)\n",
      "ValueError: in user code:\n",
      "\n",
      "    C:\\ProgramData\\Anaconda3\\envs\\tf-gpu-26\\lib\\site-packages\\keras\\engine\\training.py:853 train_function  *\n",
      "        return step_function(self, iterator)\n",
      "    C:\\ProgramData\\Anaconda3\\envs\\tf-gpu-26\\lib\\site-packages\\keras\\engine\\training.py:842 step_function  **\n",
      "        outputs = model.distribute_strategy.run(run_step, args=(data,))\n",
      "    C:\\ProgramData\\Anaconda3\\envs\\tf-gpu-26\\lib\\site-packages\\tensorflow\\python\\distribute\\distribute_lib.py:1286 run\n",
      "        return self._extended.call_for_each_replica(fn, args=args, kwargs=kwargs)\n",
      "    C:\\ProgramData\\Anaconda3\\envs\\tf-gpu-26\\lib\\site-packages\\tensorflow\\python\\distribute\\distribute_lib.py:2849 call_for_each_replica\n",
      "        return self._call_for_each_replica(fn, args, kwargs)\n",
      "    C:\\ProgramData\\Anaconda3\\envs\\tf-gpu-26\\lib\\site-packages\\tensorflow\\python\\distribute\\distribute_lib.py:3632 _call_for_each_replica\n",
      "        return fn(*args, **kwargs)\n",
      "    C:\\ProgramData\\Anaconda3\\envs\\tf-gpu-26\\lib\\site-packages\\keras\\engine\\training.py:835 run_step  **\n",
      "        outputs = model.train_step(data)\n",
      "    C:\\ProgramData\\Anaconda3\\envs\\tf-gpu-26\\lib\\site-packages\\keras\\engine\\training.py:788 train_step\n",
      "        loss = self.compiled_loss(\n",
      "    C:\\ProgramData\\Anaconda3\\envs\\tf-gpu-26\\lib\\site-packages\\keras\\engine\\compile_utils.py:201 __call__\n",
      "        loss_value = loss_obj(y_t, y_p, sample_weight=sw)\n",
      "    C:\\ProgramData\\Anaconda3\\envs\\tf-gpu-26\\lib\\site-packages\\keras\\losses.py:141 __call__\n",
      "        losses = call_fn(y_true, y_pred)\n",
      "    C:\\ProgramData\\Anaconda3\\envs\\tf-gpu-26\\lib\\site-packages\\keras\\losses.py:245 call  **\n",
      "        return ag_fn(y_true, y_pred, **self._fn_kwargs)\n",
      "    C:\\ProgramData\\Anaconda3\\envs\\tf-gpu-26\\lib\\site-packages\\tensorflow\\python\\util\\dispatch.py:206 wrapper\n",
      "        return target(*args, **kwargs)\n",
      "    C:\\ProgramData\\Anaconda3\\envs\\tf-gpu-26\\lib\\site-packages\\keras\\losses.py:1665 categorical_crossentropy\n",
      "        return backend.categorical_crossentropy(\n",
      "    C:\\ProgramData\\Anaconda3\\envs\\tf-gpu-26\\lib\\site-packages\\tensorflow\\python\\util\\dispatch.py:206 wrapper\n",
      "        return target(*args, **kwargs)\n",
      "    C:\\ProgramData\\Anaconda3\\envs\\tf-gpu-26\\lib\\site-packages\\keras\\backend.py:4839 categorical_crossentropy\n",
      "        target.shape.assert_is_compatible_with(output.shape)\n",
      "    C:\\ProgramData\\Anaconda3\\envs\\tf-gpu-26\\lib\\site-packages\\tensorflow\\python\\framework\\tensor_shape.py:1161 assert_is_compatible_with\n",
      "        raise ValueError(\"Shapes %s and %s are incompatible\" % (self, other))\n",
      "\n",
      "    ValueError: Shapes (5, 22) and (5, 3) are incompatible\n",
      "\n",
      "\n",
      "  warnings.warn(\"Estimator fit failed. The score on this train-test\"\n",
      "C:\\ProgramData\\Anaconda3\\envs\\tf-gpu-26\\lib\\site-packages\\sklearn\\model_selection\\_validation.py:615: FitFailedWarning: Estimator fit failed. The score on this train-test partition for these parameters will be set to nan. Details: \n",
      "Traceback (most recent call last):\n",
      "  File \"C:\\ProgramData\\Anaconda3\\envs\\tf-gpu-26\\lib\\site-packages\\sklearn\\model_selection\\_validation.py\", line 598, in _fit_and_score\n",
      "    estimator.fit(X_train, y_train, **fit_params)\n",
      "  File \"C:\\ProgramData\\Anaconda3\\envs\\tf-gpu-26\\lib\\site-packages\\keras\\wrappers\\scikit_learn.py\", line 219, in fit\n",
      "    return super(KerasClassifier, self).fit(x, y, **kwargs)\n",
      "  File \"C:\\ProgramData\\Anaconda3\\envs\\tf-gpu-26\\lib\\site-packages\\keras\\wrappers\\scikit_learn.py\", line 162, in fit\n",
      "    history = self.model.fit(x, y, **fit_args)\n",
      "  File \"C:\\ProgramData\\Anaconda3\\envs\\tf-gpu-26\\lib\\site-packages\\keras\\engine\\training.py\", line 1184, in fit\n",
      "    tmp_logs = self.train_function(iterator)\n",
      "  File \"C:\\ProgramData\\Anaconda3\\envs\\tf-gpu-26\\lib\\site-packages\\tensorflow\\python\\eager\\def_function.py\", line 885, in __call__\n",
      "    result = self._call(*args, **kwds)\n",
      "  File \"C:\\ProgramData\\Anaconda3\\envs\\tf-gpu-26\\lib\\site-packages\\tensorflow\\python\\eager\\def_function.py\", line 933, in _call\n",
      "    self._initialize(args, kwds, add_initializers_to=initializers)\n",
      "  File \"C:\\ProgramData\\Anaconda3\\envs\\tf-gpu-26\\lib\\site-packages\\tensorflow\\python\\eager\\def_function.py\", line 759, in _initialize\n",
      "    self._stateful_fn._get_concrete_function_internal_garbage_collected(  # pylint: disable=protected-access\n",
      "  File \"C:\\ProgramData\\Anaconda3\\envs\\tf-gpu-26\\lib\\site-packages\\tensorflow\\python\\eager\\function.py\", line 3066, in _get_concrete_function_internal_garbage_collected\n",
      "    graph_function, _ = self._maybe_define_function(args, kwargs)\n",
      "  File \"C:\\ProgramData\\Anaconda3\\envs\\tf-gpu-26\\lib\\site-packages\\tensorflow\\python\\eager\\function.py\", line 3463, in _maybe_define_function\n",
      "    graph_function = self._create_graph_function(args, kwargs)\n",
      "  File \"C:\\ProgramData\\Anaconda3\\envs\\tf-gpu-26\\lib\\site-packages\\tensorflow\\python\\eager\\function.py\", line 3298, in _create_graph_function\n",
      "    func_graph_module.func_graph_from_py_func(\n",
      "  File \"C:\\ProgramData\\Anaconda3\\envs\\tf-gpu-26\\lib\\site-packages\\tensorflow\\python\\framework\\func_graph.py\", line 1007, in func_graph_from_py_func\n",
      "    func_outputs = python_func(*func_args, **func_kwargs)\n",
      "  File \"C:\\ProgramData\\Anaconda3\\envs\\tf-gpu-26\\lib\\site-packages\\tensorflow\\python\\eager\\def_function.py\", line 668, in wrapped_fn\n",
      "    out = weak_wrapped_fn().__wrapped__(*args, **kwds)\n",
      "  File \"C:\\ProgramData\\Anaconda3\\envs\\tf-gpu-26\\lib\\site-packages\\tensorflow\\python\\framework\\func_graph.py\", line 994, in wrapper\n",
      "    raise e.ag_error_metadata.to_exception(e)\n",
      "ValueError: in user code:\n",
      "\n",
      "    C:\\ProgramData\\Anaconda3\\envs\\tf-gpu-26\\lib\\site-packages\\keras\\engine\\training.py:853 train_function  *\n",
      "        return step_function(self, iterator)\n",
      "    C:\\ProgramData\\Anaconda3\\envs\\tf-gpu-26\\lib\\site-packages\\keras\\engine\\training.py:842 step_function  **\n",
      "        outputs = model.distribute_strategy.run(run_step, args=(data,))\n",
      "    C:\\ProgramData\\Anaconda3\\envs\\tf-gpu-26\\lib\\site-packages\\tensorflow\\python\\distribute\\distribute_lib.py:1286 run\n",
      "        return self._extended.call_for_each_replica(fn, args=args, kwargs=kwargs)\n",
      "    C:\\ProgramData\\Anaconda3\\envs\\tf-gpu-26\\lib\\site-packages\\tensorflow\\python\\distribute\\distribute_lib.py:2849 call_for_each_replica\n",
      "        return self._call_for_each_replica(fn, args, kwargs)\n",
      "    C:\\ProgramData\\Anaconda3\\envs\\tf-gpu-26\\lib\\site-packages\\tensorflow\\python\\distribute\\distribute_lib.py:3632 _call_for_each_replica\n",
      "        return fn(*args, **kwargs)\n",
      "    C:\\ProgramData\\Anaconda3\\envs\\tf-gpu-26\\lib\\site-packages\\keras\\engine\\training.py:835 run_step  **\n",
      "        outputs = model.train_step(data)\n",
      "    C:\\ProgramData\\Anaconda3\\envs\\tf-gpu-26\\lib\\site-packages\\keras\\engine\\training.py:788 train_step\n",
      "        loss = self.compiled_loss(\n",
      "    C:\\ProgramData\\Anaconda3\\envs\\tf-gpu-26\\lib\\site-packages\\keras\\engine\\compile_utils.py:201 __call__\n",
      "        loss_value = loss_obj(y_t, y_p, sample_weight=sw)\n",
      "    C:\\ProgramData\\Anaconda3\\envs\\tf-gpu-26\\lib\\site-packages\\keras\\losses.py:141 __call__\n",
      "        losses = call_fn(y_true, y_pred)\n",
      "    C:\\ProgramData\\Anaconda3\\envs\\tf-gpu-26\\lib\\site-packages\\keras\\losses.py:245 call  **\n",
      "        return ag_fn(y_true, y_pred, **self._fn_kwargs)\n",
      "    C:\\ProgramData\\Anaconda3\\envs\\tf-gpu-26\\lib\\site-packages\\tensorflow\\python\\util\\dispatch.py:206 wrapper\n",
      "        return target(*args, **kwargs)\n",
      "    C:\\ProgramData\\Anaconda3\\envs\\tf-gpu-26\\lib\\site-packages\\keras\\losses.py:1665 categorical_crossentropy\n",
      "        return backend.categorical_crossentropy(\n",
      "    C:\\ProgramData\\Anaconda3\\envs\\tf-gpu-26\\lib\\site-packages\\tensorflow\\python\\util\\dispatch.py:206 wrapper\n",
      "        return target(*args, **kwargs)\n",
      "    C:\\ProgramData\\Anaconda3\\envs\\tf-gpu-26\\lib\\site-packages\\keras\\backend.py:4839 categorical_crossentropy\n",
      "        target.shape.assert_is_compatible_with(output.shape)\n",
      "    C:\\ProgramData\\Anaconda3\\envs\\tf-gpu-26\\lib\\site-packages\\tensorflow\\python\\framework\\tensor_shape.py:1161 assert_is_compatible_with\n",
      "        raise ValueError(\"Shapes %s and %s are incompatible\" % (self, other))\n",
      "\n",
      "    ValueError: Shapes (5, 22) and (5, 3) are incompatible\n",
      "\n",
      "\n",
      "  warnings.warn(\"Estimator fit failed. The score on this train-test\"\n"
     ]
    }
   ],
   "source": [
    "# multi-class classification with Keras\n",
    "import pandas\n",
    "from keras.models import Sequential\n",
    "from keras.layers import Dense\n",
    "from keras.wrappers.scikit_learn import KerasClassifier\n",
    "from keras.utils import np_utils\n",
    "from sklearn.model_selection import cross_val_score\n",
    "from sklearn.model_selection import KFold\n",
    "from sklearn.preprocessing import LabelEncoder\n",
    "from sklearn.pipeline import Pipeline\n",
    "# load dataset\n",
    "location = \"C:/DevelopmentPlayground/Datasets/iris.csv\"\n",
    "dataframe = pandas.read_csv(location)\n",
    "dataset = dataframe.values\n",
    "X = dataset[:,0:4].astype(float)\n",
    "Y = dataset[:,4]\n",
    "# encode class values as integers\n",
    "encoder = LabelEncoder()\n",
    "encoder.fit(Y)\n",
    "encoded_Y = encoder.transform(Y)\n",
    "# convert integers to dummy variables (i.e. one hot encoded)\n",
    "dummy_y = np_utils.to_categorical(encoded_Y)\n",
    "\n",
    "# define baseline model\n",
    "def baseline_model():\n",
    "    # create model\n",
    "    model = Sequential()\n",
    "    model.add(Dense(8, input_dim=4, activation='relu'))\n",
    "    model.add(Dense(3, activation='softmax'))\n",
    "    # Compile model\n",
    "    model.compile(loss='categorical_crossentropy', optimizer='adam', metrics=['accuracy'])\n",
    "    return model\n",
    "\n",
    "estimator = KerasClassifier(build_fn=baseline_model, epochs=200, batch_size=5, verbose=0)\n",
    "kfold = KFold(n_splits=10, shuffle=True)\n",
    "results = cross_val_score(estimator, X, dummy_y, cv=kfold)\n",
    "print(\"Baseline: %.2f%% (%.2f%%)\" % (results.mean()*100, results.std()*100))"
   ]
  },
  {
   "cell_type": "code",
   "execution_count": null,
   "id": "44fb2e28",
   "metadata": {},
   "outputs": [],
   "source": []
  }
 ],
 "metadata": {
  "kernelspec": {
   "display_name": "tf-gpu-26",
   "language": "python",
   "name": "tf-gpu-26"
  },
  "language_info": {
   "codemirror_mode": {
    "name": "ipython",
    "version": 3
   },
   "file_extension": ".py",
   "mimetype": "text/x-python",
   "name": "python",
   "nbconvert_exporter": "python",
   "pygments_lexer": "ipython3",
   "version": "3.9.7"
  }
 },
 "nbformat": 4,
 "nbformat_minor": 5
}
